Workbook

Sheet Raw Cost
A1: Product | B1: Price | F1: 9.2
A2: Apples, Granny | B2: 38 | C2: CONCHA | D2: 28 | H2: $15.00 for Ranch
A3: Apples, Gala | B3: 45 | C3: MIKE | D3: 24 | F3: 3.5 | J3: 44287 | K3: 44910 | L3: 45092 | M3: 45200 | N3: 45762
A4: Asparagus, 11# standard | B4: 36
A5: Beans, Various, #10 can | B5: 9
A6: Beets, Cut 25# | B6: 18 | H6: $18.40/ 100 cups cost | J6: 19.8 | K6: 20.67 | L6: 20.58 | M6: 18.4 | N6: 20.86
A7: Beets, Candystripe 25# | B7: 35
A8: Beets, Gold 25# | B8: 34
A9: Blueberries 1/2 Pint | B9: 36 | H9: $10.20 cost per 50ct case
A10: Blueberries 1 Pint | B10: 72
A11: Bok Choy | B11: 43.79
A12: Broccoli Crowns | B12: 22
A13: Broccoli 14 ct | B13: 22
A14: Broccoli Flor 6/3# | B14: 47
A15: Brussel Sprouts | B15: 36
A16: Cabbage, Bag | B16: 17
A17: Cabbage, Red | B17: 25
A18: Cabbage, Savoy | B18: 44
A19: Canteloupes | B19: 20
A20: Carrots,50# | B20: 30
A21: Carrots, Baby Slims 4/5# | B21: 32
... A49: Onions, Yellow 50# | B49: 14
A50: Oranges, 113 ct | B50: 40 | C50: 33 MIKE
A51: Oranges, 125 ct | B51: 26
A52: Oranges, Blood 88ct | B52: 47
A53: Papaya, 9ct | B53: 62
A54: Parsnips, 25# | B54: 38
A55: Pears, Bosc | B55: 41
A56: Pears, Green | B56: 39
A57: Peppers, Green | B57: 46
A58: Peppers, Red | B58: 42
A59: Peppers, Yellow | B59: 39
A60: Pineapples | B60: 18
A61: Potatoes, 90 ct | B61: 20
A62: Potatoes, Red A | B62: 18
... A86: Watermelon Radish 20# | B86: 32
A87: Pepper Mix | B87: =SUM((B57/18)*6)+((B58/15)*2)+((B59/15)*2) -> 26.133333
A88: Pico de Gallo | B88: =SUM((B81/20)*5)+((B49/35)*5)+((B37/10)*1)+((B26/12)*1) -> 18.866667
A89: Fruit Mix | B89: =(SUM(B19/16,B31/18,B36/15,B60/8.5)) -> 7.1565359
A90: Broccoli Slaw | B90: =SUM(((B12/10)*10)+((B17/35)*1)+((B20/35))*2) -> 24.428571
...

Sheet Packaging Cost
A1: PACKAGING TYPE | B1: BOX COST | C1: BAG COST | D1: TRAY / CHEMICAL | E1: LABELS / TAPE | F1: TOTAL COST
A2: 4/5 NEW KRAFT | B2: 0.75 | C2: 0.38 | D2: 0 | E2: 0.1 | F2: =SUM(B2:E2) -> 1.23
A3: 2/10 NEW KRAFT | B3: 0.75 | C3: 0.75 | D3: 0 | E3: 0.1 | F3: =SUM(B3:E3) -> 1.6
A4: 2/5 TUB | B4: 0.67 | C4: 0.13 | D4: 0 | E4: 0.1 | F4: =SUM(B4:E4) -> 0.9
A5: 1/5 TUB | B5: 0.42 | C5: 0.07 | D5: 0 | E5: 0.1 | F5: =SUM(B5:E5) -> 0.59
A6: 2/5 FRUIT TRAY | B6: 1.1 | C6: 0 | D6: 2.02 | E6: 0.1 | F6: =SUM(B6:E6) -> 3.22
A7: 2/5 ONION TRAY | B7: 1.1 | C7: 0 | D7: 1.32 | E7: 0.1 | F7: =SUM(B7:E7) -> 2.52
A8: 1/5 FRUIT TRAY | B8: 0.65 | C8: 0 | D8: 1.01 | E8: 0.1 | F8: =SUM(B8:E8) -> 1.76
A9: 1/5 ONION TRAY | B9: 0.65 | C9: 0 | D9: 0.66 | E9: 0.1 | F9: =SUM(B9:E9) -> 1.41
A10: 4/3 TUB | B10: 0.67 | C10: 0.38 | D10: 0 | E10: 0.1 | F10: =SUM(B10:E10) -> 1.15
A11: SNAKPAK 50CT | B11: 0.75 | C11: 1.75 | D11: 0 | E11: 0.1 | F11: =SUM(B11:E11) -> 2.6
A12: SNAKPAK 100CT | B12: 0.75 | C12: 3.5 | D12: 0 | E12: 0.1 | F12: =SUM(B12:E12) -> 4.35
A13: 4/3 NEW KRAFT | B13: 0.75 | C13: 0.38 | D13: 0 | E13: 0.1 | F13: =SUM(B13:E13) -> 1.23
A14: 5# WHOLE PRODUCE | C14: 0.1 | D14: 0 | E14: 0.1 | F14: =SUM(B14:E14) -> 0.2
A15: SNAKPAK 50CT 10# TRAY | B15: 1.01 | C15: 1.75 | D15: 0 | E15: 0.1 | F15: =SUM(B15:E15) -> 2.86
A16: PARTY TRAY | B16: 0 | C16: 0 | D16: 2 | E16: 0.1 | F16: =SUM(B16:E16) -> 2.1
A17: PICO DE GALLO | B17: 1 | C17: 0 | D17: 4.36 | E17: 0.1 | F17: =SUM(B17:E17) -> 5.46
A18: 2/4 SMALL COLLARD | B18: 0.42 | C18: 0.16 | D18: 0 | E18: 0.1 | F18: =SUM(B18:E18) -> 0.68
A19: 10X1LBS BAG | B19: 0.67 | C19: 3.9 | E19: 0.1 | F19: =SUM(B19:E19) -> 4.67
A20: APPLE SNACK PACK 50CT | B20: 0.75 | C20: 1.75 | D20: 1.5 | E20: 0.1 | F20: =SUM(B20:E20) -> 4.1
A21: APPLE SNACK PACK 100CT | B21: 0.75 | C21: 3.5 | D21: 3 | E21: 0.1 | F21: =SUM(B21:E21) -> 7.35
A22: APPLE BULK 4/3 | B22: 0.75 | C22: 0.38 | D22: 1.5 | E22: 0.1 | F22: =SUM(B22:E22) -> 2.73
A23: APPLE BULK 4/5 | B23: 0.75 | C23: 0.25 | D23: 1.5 | E23: 0.1 | F23: =SUM(B23:E23) -> 2.6
A24: POTATOES 2/5 | B24: 0.75 | C24: 0.75 | D24: 0.75 | E24: 0.1 | F24: =SUM(B24:E24) -> 2.35
A25: POTATOES 4/5 | B25: 0.75 | C25: 0.25 | D25: 0.75 | E25: 0.1 | F25: =SUM(B25:E25) -> 1.85
A26: POTATOES 2/10 | B26: 0.75 | C26: 0.75 | D26: 0.75 | E26: 0.1 | F26: =SUM(B26:E26) -> 2.35
A27: TOMATO BAG 4/5 | B27: 0.75 | C27: 1.75 | E27: 0.1 | F27: =SUM(B27:E27) -> 2.6
A28: 8CT FRUIT CUPS | B28: 0.67 | C28: 2.24 | E28: 0.1 | F28: =SUM(B28:E28) -> 3.01
A29: 4/2# MCENTIRE | B29: 0.42 | C29: 0.2 | E29: 0.1 | F29: =SUM(B29:E29) -> 0.72
A30: PARTY TRAY | D30: 1.9 | E30: 0.1 | F30: =SUM(B30:E30) -> 2
F31: =SUM(B31:E31) -> 0
F32: =SUM(B32:E32) -> 0
F33: =SUM(B33:E33) -> 0
F34: =SUM(B34:E34) -> 0
F35: =SUM(B35:E35) -> 0

Sheet Master Item List
A1: DESCRIPTION | B1: ITEM CODE | C1: Base Product | D1: Ranch? | E1: Snakpak or Foodservice? | F1: Packaging Type | G1: Yield (LB/Prod) | H1: Cost/LB (Price/Yield) | I1: Cost/Oz | J1: CASE WT | K1: LABOR | L1: PACKAGING | M1: UNIT COST | N1: 0.25 | O1: 0.3 | P1: 0.35 | Q1: 0.4 | R1: 0.45 | S1: 25% Rounded | T1: 30% Rounded | U1: 35% Rounded | V1: 40% Rounded | W1: 45% Rounded
A2: ACORN SQUASH, DICED (4X5#CASE) | B2: AC | C2: Squash, Acorn | D2: No | E2: Foodservice | F2: 4/5 NEW KRAFT | G2: 20 | H2: =VLOOKUP($C2,'Raw Cost'!$A$1:$B$484,2,FALSE)/G2 -> 1.3 | I2: =H2/16 -> 0.08125 | J2: 20 | K2: 0.25 | L2: =VLOOKUP($F2,'Packaging Cost'!$A$1:$F$43,6,FALSE) -> 1.23 | M2: =IF($E2="Snakpak",(($J2*H2)+($K2*'Labor Cost'!$A$2)+L2)+2.25,($J2*H2)+($K2*'Labor Cost'!$A$2)+L2+1) -> 34.105 | N2: =IF($D2="No",$M2*1.25,($M2*1.25)+15) -> 42.63125 | O2: =IF($D2="No",$M2*1.3,($M2*1.3)+15) -> 44.3365 | P2: =IF($D2="No",$M2*1.35,($M2*1.35)+15) -> 46.04175 | Q2: =IF($D2="No",$M2*1.4,($M2*1.4)+15) -> 47.747 | R2: =IF($D2="No",$M2*1.45,($M2*1.45)+15) -> 49.45225 | S2: =MROUND(N2,0.25) -> 42.75 | T2: =MROUND(O2,0.25) -> 44.25 | U2: =MROUND(P2,0.25) -> 46 | V2: =MROUND(Q2,0.25) -> 47.75 | W2: =MROUND(R2,0.25) -> 49.5
A3: APPLE, GREEN DICED (4X5# CASE) | B3: APD | C3: Apples, Granny | D3: No | E3: Foodservice | F3: APPLE BULK 4/5 | G3: 29 | H3: =VLOOKUP($C3,'Raw Cost'!$A$1:$B$484,2,FALSE)/G3 -> 1.3103448 | I3: =H3/16 -> 0.081896552 | J3: 20 | K3: 0.25 | L3: =VLOOKUP($F3,'Packaging Cost'!$A$1:$F$43,6,FALSE) -> 2.6 | M3: =IF($E3="Snakpak",(($J3*H3)+($K3*'Labor Cost'!$A$2)+L3)+2.25,($J3*H3)+($K3*'Labor Cost'!$A$2)+L3+1) -> 35.681897 | N3: =IF($D3="No",$M3*1.25,($M3*1.25)+15) -> 44.602371 | O3: =IF($D3="No",$M3*1.3,($M3*1.3)+15) -> 46.386466 | P3: =IF($D3="No",$M3*1.35,($M3*1.35)+15) -> 48.17056 | Q3: =IF($D3="No",$M3*1.4,($M3*1.4)+15) -> 49.954655 | R3: =IF($D3="No",$M3*1.45,($M3*1.45)+15) -> 51.73875 | S3: =MROUND(N3,0.25) -> 44.5 | T3: =MROUND(O3,0.25) -> 46.5 | U3: =MROUND(P3,0.25) -> 48.25 | V3: =MROUND(Q3,0.25) -> 50 | W3: =MROUND(R3,0.25) -> 51.75
A4: APPLE, GREEN WEDGES (10X1# CASE) | B4: GRW10 | C4: Apples, Granny | D4: No | E4: Foodservice | F4: 10X1LBS BAG | G4: 29 | H4: =VLOOKUP($C4,'Raw Cost'!$A$1:$B$484,2,FALSE)/G4 -> 1.3103448 | I4: =H4/16 -> 0.081896552 | J4: 10 | K4: 0.25 | L4: =VLOOKUP($F4,'Packaging Cost'!$A$1:$F$43,6,FALSE) -> 4.67 | M4: =IF($E4="Snakpak",(($J4*H4)+($K4*'Labor Cost'!$A$2)+L4)+2.25,($J4*H4)+($K4*'Labor Cost'!$A$2)+L4+1) -> 24.648448 | N4: =IF($D4="No",$M4*1.25,($M4*1.25)+15) -> 30.81056 | O4: =IF($D4="No",$M4*1.3,($M4*1.3)+15) -> 32.042983 | P4: =IF($D4="No",$M4*1.35,($M4*1.35)+15) -> 33.275405 | Q4: =IF($D4="No",$M4*1.4,($M4*1.4)+15) -> 34.507828 | R4: =IF($D4="No",$M4*1.45,($M4*1.45)+15) -> 35.74025 | S4: =MROUND(N4,0.25) -> 30.75 | T4: =MROUND(O4,0.25) -> 32 | U4: =MROUND(P4,0.25) -> 33.25 | V4: =MROUND(Q4,0.25) -> 34.5 | W4: =MROUND(R4,0.25) -> 35.75
A5: APPLE, GREEN WEDGES (4 X 3) | B5: GRW | C5: Apples, Granny | D5: No | E5: Foodservice | F5: 4/3 TUB | G5: 29 | H5: =VLOOKUP($C5,'Raw Cost'!$A$1:$B$484,2,FALSE)/G5 -> 1.3103448 | I5: =H5/16 -> 0.081896552 | J5: 12 | K5: 0.25 | L5: =VLOOKUP($F5,'Packaging Cost'!$A$1:$F$43,6,FALSE) -> 1.15 | M5: =IF($E5="Snakpak",(($J5*H5)+($K5*'Labor Cost'!$A$2)+L5)+2.25,($J5*H5)+($K5*'Labor Cost'!$A$2)+L5+1) -> 23.749138 | N5: =IF($D5="No",$M5*1.25,($M5*1.25)+15) -> 29.686422 | O5: =IF($D5="No",$M5*1.3,($M5*1.3)+15) -> 30.873879 | P5: =IF($D5="No",$M5*1.35,($M5*1.35)+15) -> 32.061336 | Q5: =IF($D5="No",$M5*1.4,($M5*1.4)+15) -> 33.248793 | R5: =IF($D5="No",$M5*1.45,($M5*1.45)+15) -> 34.43625 | S5: =MROUND(N5,0.25) -> 29.75 | T5: =MROUND(O5,0.25) -> 30.75 | U5: =MROUND(P5,0.25) -> 32 | V5: =MROUND(Q5,0.25) -> 33.25 | W5: =MROUND(R5,0.25) -> 34.5
A6: APPLE, RED DICED (4X5# CASE) | B6: DRA | C6: Apples, Gala | D6: No | E6: Foodservice | F6: APPLE BULK 4/5 | G6: 29 | H6: =VLOOKUP($C6,'Raw Cost'!$A$1:$B$484,2,FALSE)/G6 -> 1.5517241 | I6: =H6/16 -> 0.096982759 | J6: 20 | K6: 0.25 | L6: =VLOOKUP($F6,'Packaging Cost'!$A$1:$F$43,6,FALSE) -> 2.6 | M6: =IF($E6="Snakpak",(($J6*H6)+($K6*'Labor Cost'!$A$2)+L6)+2.25,($J6*H6)+($K6*'Labor Cost'!$A$2)+L6+1) -> 40.509483 | N6: =IF($D6="No",$M6*1.25,($M6*1.25)+15) -> 50.636853 | O6: =IF($D6="No",$M6*1.3,($M6*1.3)+15) -> 52.662328 | P6: =IF($D6="No",$M6*1.35,($M6*1.35)+15) -> 54.687802 | Q6: =IF($D6="No",$M6*1.4,($M6*1.4)+15) -> 56.713276 | R6: =IF($D6="No",$M6*1.45,($M6*1.45)+15) -> 58.73875 | S6: =MROUND(N6,0.25) -> 50.75 | T6: =MROUND(O6,0.25) -> 52.75 | U6: =MROUND(P6,0.25) -> 54.75 | V6: =MROUND(Q6,0.25) -> 56.75 | W6: =MROUND(R6,0.25) -> 58.75
A7: APPLE, RED WEDGES (10X1#CASE) | B7: GW10 | C7: Apples, Gala | D7: No | E7: Foodservice | F7: 10X1LBS BAG | G7: 29 | H7: =VLOOKUP($C7,'Raw Cost'!$A$1:$B$484,2,FALSE)/G7 -> 1.5517241 | I7: =H7/16 -> 0.096982759 | J7: 10 | K7: 0.25 | L7: =VLOOKUP($F7,'Packaging Cost'!$A$1:$F$43,6,FALSE) -> 4.67 | M7: =IF($E7="Snakpak",(($J7*H7)+($K7*'Labor Cost'!$A$2)+L7)+2.25,($J7*H7)+($K7*'Labor Cost'!$A$2)+L7+1) -> 27.062241 | N7: =IF($D7="No",$M7*1.25,($M7*1.25)+15) -> 33.827802 | O7: =IF($D7="No",$M7*1.3,($M7*1.3)+15) -> 35.180914 | P7: =IF($D7="No",$M7*1.35,($M7*1.35)+15) -> 36.534026 | Q7: =IF($D7="No",$M7*1.4,($M7*1.4)+15) -> 37.887138 | R7: =IF($D7="No",$M7*1.45,($M7*1.45)+15) -> 39.24025 | S7: =MROUND(N7,0.25) -> 33.75 | T7: =MROUND(O7,0.25) -> 35.25 | U7: =MROUND(P7,0.25) -> 36.5 | V7: =MROUND(Q7,0.25) -> 38 | W7: =MROUND(R7,0.25) -> 39.25
A8: APPLE, RED WEDGES (4X3#CASE) | B8: GW | C8: Apples, Gala | D8: No | E8: Foodservice | F8: APPLE BULK 4/3 | G8: 29 | H8: =VLOOKUP($C8,'Raw Cost'!$A$1:$B$484,2,FALSE)/G8 -> 1.5517241 | I8: =H8/16 -> 0.096982759 | J8: 12 | K8: 0.25 | L8: =VLOOKUP($F8,'Packaging Cost'!$A$1:$F$43,6,FALSE) -> 2.73 | M8: =IF($E8="Snakpak",(($J8*H8)+($K8*'Labor Cost'!$A$2)+L8)+2.25,($J8*H8)+($K8*'Labor Cost'!$A$2)+L8+1) -> 28.22569 | N8: =IF($D8="No",$M8*1.25,($M8*1.25)+15) -> 35.282112 | O8: =IF($D8="No",$M8*1.3,($M8*1.3)+15) -> 36.693397 | P8: =IF($D8="No",$M8*1.35,($M8*1.35)+15) -> 38.104681 | Q8: =IF($D8="No",$M8*1.4,($M8*1.4)+15) -> 39.515966 | R8: =IF($D8="No",$M8*1.45,($M8*1.45)+15) -> 40.92725 | S8: =MROUND(N8,0.25) -> 35.25 | T8: =MROUND(O8,0.25) -> 36.75 | U8: =MROUND(P8,0.25) -> 38 | V8: =MROUND(Q8,0.25) -> 39.5 | W8: =MROUND(R8,0.25) -> 41
A9: BEETS, CANDY STRIPE DICED (2X5#CASE) | B9: BET | C9: Beets, Candystripe 25# | D9: No | E9: Foodservice | F9: 2/5 TUB | G9: 18 | H9: =VLOOKUP($C9,'Raw Cost'!$A$1:$B$484,2,FALSE)/G9 -> 1.9444444 | I9: =H9/16 -> 0.12152778 | J9: 10 | K9: 0.25 | L9: =VLOOKUP($F9,'Packaging Cost'!$A$1:$F$43,6,FALSE) -> 0.9 | M9: =IF($E9="Snakpak",(($J9*H9)+($K9*'Labor Cost'!$A$2)+L9)+2.25,($J9*H9)+($K9*'Labor Cost'!$A$2)+L9+1) -> 27.219444 | N9: =IF($D9="No",$M9*1.25,($M9*1.25)+15) -> 34.024306 | O9: =IF($D9="No",$M9*1.3,($M9*1.3)+15) -> 35.385278 | P9: =IF($D9="No",$M9*1.35,($M9*1.35)+15) -> 36.74625 | Q9: =IF($D9="No",$M9*1.4,($M9*1.4)+15) -> 38.107222 | R9: =IF($D9="No",$M9*1.45,($M9*1.45)+15) -> 39.468194 | S9: =MROUND(N9,0.25) -> 34 | T9: =MROUND(O9,0.25) -> 35.5 | U9: =MROUND(P9,0.25) -> 36.75 | V9: =MROUND(Q9,0.25) -> 38 | W9: =MROUND(R9,0.25) -> 39.5
A10: BEETS, DICED (2X5#CASE) | B10: BETD | C10: Beets, Cut 25# | D10: No | E10: Foodservice | F10: 2/5 TUB | G10: 18 | H10: =VLOOKUP($C10,'Raw Cost'!$A$1:$B$484,2,FALSE)/G10 -> 1 | I10: =H10/16 -> 0.0625 | J10: 10 | K10: 0.25 | L10: =VLOOKUP($F10,'Packaging Cost'!$A$1:$F$43,6,FALSE) -> 0.9 | M10: =IF($E10="Snakpak",(($J10*H10)+($K10*'Labor Cost'!$A$2)+L10)+2.25,($J10*H10)+($K10*'Labor Cost'!$A$2)+L10+1) -> 17.775 | N10: =IF($D10="No",$M10*1.25,($M10*1.25)+15) -> 22.21875 | O10: =IF($D10="No",$M10*1.3,($M10*1.3)+15) -> 23.1075 | P10: =IF($D10="No",$M10*1.35,($M10*1.35)+15) -> 23.99625 | Q10: =IF($D10="No",$M10*1.4,($M10*1.4)+15) -> 24.885 | R10: =IF($D10="No",$M10*1.45,($M10*1.45)+15) -> 25.77375 | S10: =MROUND(N10,0.25) -> 22.25 | T10: =MROUND(O10,0.25) -> 23 | U10: =MROUND(P10,0.25) -> 24 | V10: =MROUND(Q10,0.25) -> 25 | W10: =MROUND(R10,0.25) -> 25.75
A11: BEETS, GOLD DICED (2X5#CASE) | B11: BET | C11: Beets, Gold 25# | D11: No | E11: Foodservice | F11: 2/5 TUB | G11: 18 | H11: =VLOOKUP($C11,'Raw Cost'!$A$1:$B$484,2,FALSE)/G11 -> 1.8888889 | I11: =H11/16 -> 0.11805556 | J11: 10 | K11: 0.25 | L11: =VLOOKUP($F11,'Packaging Cost'!$A$1:$F$43,6,FALSE) -> 0.9 | M11: =IF($E11="Snakpak",(($J11*H11)+($K11*'Labor Cost'!$A$2)+L11)+2.25,($J11*H11)+($K11*'Labor Cost'!$A$2)+L11+1) -> 26.663889 | N11: =IF($D11="No",$M11*1.25,($M11*1.25)+15) -> 33.329861 | O11: =IF($D11="No",$M11*1.3,($M11*1.3)+15) -> 34.663056 | P11: =IF($D11="No",$M11*1.35,($M11*1.35)+15) -> 35.99625 | Q11: =IF($D11="No",$M11*1.4,($M11*1.4)+15) -> 37.329444 | R11: =IF($D11="No",$M11*1.45,($M11*1.45)+15) -> 38.662639 | S11: =MROUND(N11,0.25) -> 33.25 | T11: =MROUND(O11,0.25) -> 34.75 | U11: =MROUND(P11,0.25) -> 36 | V11: =MROUND(Q11,0.25) -> 37.25 | W11: =MROUND(R11,0.25) -> 38.75
A12: BOK CHOY, CHOPPED (4 X 5# CASE) | B12: BC | C12: Bok Choy | D12: No | E12: Foodservice | F12: 4/5 NEW KRAFT | G12: 30 | H12: =VLOOKUP($C12,'Raw Cost'!$A$1:$B$484,2,FALSE)/G12 -> 1.4596667 | I12: =H12/16 -> 0.091229167 | J12: 20 | K12: 0.25 | L12: =VLOOKUP($F12,'Packaging Cost'!$A$1:$F$43,6,FALSE) -> 1.23 | M12: =IF($E12="Snakpak",(($J12*H12)+($K12*'Labor Cost'!$A$2)+L12)+2.25,($J12*H12)+($K12*'Labor Cost'!$A$2)+L12+1) -> 37.298333 | N12: =IF($D12="No",$M12*1.25,($M12*1.25)+15) -> 46.622917 | O12: =IF($D12="No",$M12*1.3,($M12*1.3)+15) -> 48.487833 | P12: =IF($D12="No",$M12*1.35,($M12*1.35)+15) -> 50.35275 | Q12: =IF($D12="No",$M12*1.4,($M12*1.4)+15) -> 52.217667 | R12: =IF($D12="No",$M12*1.45,($M12*1.45)+15) -> 54.082583 | S12: =MROUND(N12,0.25) -> 46.5 | T12: =MROUND(O12,0.25) -> 48.5 | U12: =MROUND(P12,0.25) -> 50.25 | V12: =MROUND(Q12,0.25) -> 52.25 | W12: =MROUND(R12,0.25) -> 54
A13: BROCCOLI FLORETS (4X3# CASE) | B13: BROF | C13: Broccoli Crowns | D13: No | E13: Foodservice | F13: 4/3 NEW KRAFT | G13: 15 | H13: =VLOOKUP($C13,'Raw Cost'!$A$1:$B$484,2,FALSE)/G13 -> 1.4666667 | I13: =H13/16 -> 0.091666667 | J13: 12 | K13: 0.25 | L13: =VLOOKUP($F13,'Packaging Cost'!$A$1:$F$43,6,FALSE) -> 1.23 | M13: =IF($E13="Snakpak",(($J13*H13)+($K13*'Labor Cost'!$A$2)+L13)+2.25,($J13*H13)+($K13*'Labor Cost'!$A$2)+L13+1) -> 25.705 | N13: =IF($D13="No",$M13*1.25,($M13*1.25)+15) -> 32.13125 | O13: =IF($D13="No",$M13*1.3,($M13*1.3)+15) -> 33.4165 | P13: =IF($D13="No",$M13*1.35,($M13*1.35)+15) -> 34.70175 | Q13: =IF($D13="No",$M13*1.4,($M13*1.4)+15) -> 35.987 | R13: =IF($D13="No",$M13*1.45,($M13*1.45)+15) -> 37.27225 | S13: =MROUND(N13,0.25) -> 32.25 | T13: =MROUND(O13,0.25) -> 33.5 | U13: =MROUND(P13,0.25) -> 34.75 | V13: =MROUND(Q13,0.25) -> 36 | W13: =MROUND(R13,0.25) -> 37.25
A14: BROCCOLI FLORETS (6x3#CASE) | B14: BROF63 | C14: Broccoli Crowns | D14: No | E14: Foodservice | F14: 4/5 NEW KRAFT | G14: 15 | H14: =VLOOKUP($C14,'Raw Cost'!$A$1:$B$484,2,FALSE)/G14 -> 1.4666667 | I14: =H14/16 -> 0.091666667 | J14: 18 | K14: 0.25 | L14: =VLOOKUP($F14,'Packaging Cost'!$A$1:$F$43,6,FALSE) -> 1.23 | M14: =IF($E14="Snakpak",(($J14*H14)+($K14*'Labor Cost'!$A$2)+L14)+2.25,($J14*H14)+($K14*'Labor Cost'!$A$2)+L14+1) -> 34.505 | N14: =IF($D14="No",$M14*1.25,($M14*1.25)+15) -> 43.13125 | O14: =IF($D14="No",$M14*1.3,($M14*1.3)+15) -> 44.8565 | P14: =IF($D14="No",$M14*1.35,($M14*1.35)+15) -> 46.58175 | Q14: =IF($D14="No",$M14*1.4,($M14*1.4)+15) -> 48.307 | R14: =IF($D14="No",$M14*1.45,($M14*1.45)+15) -> 50.03225 | S14: =MROUND(N14,0.25) -> 43.25 | T14: =MROUND(O14,0.25) -> 44.75 | U14: =MROUND(P14,0.25) -> 46.5 | V14: =MROUND(Q14,0.25) -> 48.25 | W14: =MROUND(R14,0.25) -> 50
A15: BROCCOLI SLAW (4X3#CASE) | B15: BRS | C15: Broccoli Slaw | D15: No | E15: Foodservice | F15: 4/3 TUB | G15: 15 | H15: =VLOOKUP($C15,'Raw Cost'!$A$1:$B$484,2,FALSE)/G15 -> 1.6285714 | I15: =H15/16 -> 0.10178571 | J15: 12 | K15: 0.15 | L15: =VLOOKUP($F15,'Packaging Cost'!$A$1:$F$43,6,FALSE) -> 1.15 | M15: =IF($E15="Snakpak",(($J15*H15)+($K15*'Labor Cost'!$A$2)+L15)+2.25,($J15*H15)+($K15*'Labor Cost'!$A$2)+L15) -> 24.217857 | N15: =IF($D15="No",$M15*1.25,($M15*1.25)+15) -> 30.272321 | O15: =IF($D15="No",$M15*1.3,($M15*1.3)+15) -> 31.483214 | P15: =IF($D15="No",$M15*1.35,($M15*1.35)+15) -> 32.694107 | Q15: =IF($D15="No",$M15*1.4,($M15*1.4)+15) -> 33.905 | R15: =IF($D15="No",$M15*1.45,($M15*1.45)+15) -> 35.115893 | S15: =MROUND(N15,0.25) -> 30.25 | T15: =MROUND(O15,0.25) -> 31.5 | U15: =MROUND(P15,0.25) -> 32.75 | V15: =MROUND(Q15,0.25) -> 34 | W15: =MROUND(R15,0.25) -> 35
A16: BRUSSEL SPROUTS, SHREDDED (4X5# CASE) | B16: BRU | C16: Brussel Sprouts | D16: No | E16: Foodservice | F16: 4/5 NEW KRAFT | G16: 20 | H16: =VLOOKUP($C16,'Raw Cost'!$A$1:$B$484,2,FALSE)/G16 -> 1.8 | I16: =H16/16 -> 0.1125 | J16: 20 | K16: 0.35 | L16: =VLOOKUP($F16,'Packaging Cost'!$A$1:$F$43,6,FALSE) -> 1.23 | M16: =IF($E16="Snakpak",(($J16*H16)+($K16*'Labor Cost'!$A$2)+L16)+2.25,($J16*H16)+($K16*'Labor Cost'!$A$2)+L16+1) -> 46.455 | N16: =IF($D16="No",$M16*1.25,($M16*1.25)+15) -> 58.06875 | O16: =IF($D16="No",$M16*1.3,($M16*1.3)+15) -> 60.3915 | P16: =IF($D16="No",$M16*1.35,($M16*1.35)+15) -> 62.71425 | Q16: =IF($D16="No",$M16*1.4,($M16*1.4)+15) -> 65.037 | R16: =IF($D16="No",$M16*1.45,($M16*1.45)+15) -> 67.35975 | S16: =MROUND(N16,0.25) -> 58 | T16: =MROUND(O16,0.25) -> 60.5 | U16: =MROUND(P16,0.25) -> 62.75 | V16: =MROUND(Q16,0.25) -> 65 | W16: =MROUND(R16,0.25) -> 67.25
A17: BRUSSELS SPROUT, TRIMMED & HALVED (4X5# CASE) | B17: BRUH | C17: Brussel Sprouts | D17: No | E17: Foodservice | F17: 4/5 NEW KRAFT | G17: 20 | H17: =VLOOKUP($C17,'Raw Cost'!$A$1:$B$484,2,FALSE)/G17 -> 1.8 | I17: =H17/16 -> 0.1125 | J17: 20 | K17: 0.75 | L17: =VLOOKUP($F17,'Packaging Cost'!$A$1:$F$43,6,FALSE) -> 1.23 | M17: =IF($E17="Snakpak",(($J17*H17)+($K17*'Labor Cost'!$A$2)+L17)+2.25,($J17*H17)+($K17*'Labor Cost'!$A$2)+L17+1) -> 55.855 | N17: =IF($D17="No",$M17*1.25,($M17*1.25)+15) -> 69.81875 | O17: =IF($D17="No",$M17*1.3,($M17*1.3)+15) -> 72.6115 | P17: =IF($D17="No",$M17*1.35,($M17*1.35)+15) -> 75.40425 | Q17: =IF($D17="No",$M17*1.4,($M17*1.4)+15) -> 78.197 | R17: =IF($D17="No",$M17*1.45,($M17*1.45)+15) -> 80.98975 | S17: =MROUND(N17,0.25) -> 69.75 | T17: =MROUND(O17,0.25) -> 72.5 | U17: =MROUND(P17,0.25) -> 75.5 | V17: =MROUND(Q17,0.25) -> 78.25 | W17: =MROUND(R17,0.25) -> 81
A18: BUTTERNUT SQUASH DICED (20# CASE) | B18: BD | C18: Squash, Butternut | D18: No | E18: Foodservice | F18: 4/5 NEW KRAFT | G18: 26 | H18: =VLOOKUP($C18,'Raw Cost'!$A$1:$B$484,2,FALSE)/G18 -> 1 | I18: =H18/16 -> 0.0625 | J18: 20 | K18: 0.27 | L18: =VLOOKUP($F18,'Packaging Cost'!$A$1:$F$43,6,FALSE) -> 1.23 | M18: =IF($E18="Snakpak",(($J18*H18)+($K18*'Labor Cost'!$A$2)+L18)+2.25,($J18*H18)+($K18*'Labor Cost'!$A$2)+L18+1) -> 28.575 | N18: =IF($D18="No",$M18*1.25,($M18*1.25)+15) -> 35.71875 | O18: =IF($D18="No",$M18*1.3,($M18*1.3)+15) -> 37.1475 | P18: =IF($D18="No",$M18*1.35,($M18*1.35)+15) -> 38.57625 | Q18: =IF($D18="No",$M18*1.4,($M18*1.4)+15) -> 40.005 | R18: =IF($D18="No",$M18*1.45,($M18*1.45)+15) -> 41.43375 | S18: =MROUND(N18,0.25) -> 35.75 | T18: =MROUND(O18,0.25) -> 37.25 | U18: =MROUND(P18,0.25) -> 38.5 | V18: =MROUND(Q18,0.25) -> 40 | W18: =MROUND(R18,0.25) -> 41.5
A19: CABBAGE, CHOPPED (20# CASE) | B19: CHCAB | C19: Cabbage, Bag | D19: No | E19: Foodservice | F19: 4/5 NEW KRAFT | G19: 35 | H19: =VLOOKUP($C19,'Raw Cost'!$A$1:$B$484,2,FALSE)/G19 -> 0.48571429 | I19: =H19/16 -> 0.030357143 | J19: 20 | K19: 0.25 | L19: =VLOOKUP($F19,'Packaging Cost'!$A$1:$F$43,6,FALSE) -> 1.23 | M19: =IF($E19="Snakpak",(($J19*H19)+($K19*'Labor Cost'!$A$2)+L19)+2.25,($J19*H19)+($K19*'Labor Cost'!$A$2)+L19+1) -> 17.819286 | N19: =IF($D19="No",$M19*1.25,($M19*1.25)+15) -> 22.274107 | O19: =IF($D19="No",$M19*1.3,($M19*1.3)+15) -> 23.165071 | P19: =IF($D19="No",$M19*1.35,($M19*1.35)+15) -> 24.056036 | Q19: =IF($D19="No",$M19*1.4,($M19*1.4)+15) -> 24.947 | R19: =IF($D19="No",$M19*1.45,($M19*1.45)+15) -> 25.837964 | S19: =MROUND(N19,0.25) -> 22.25 | T19: =MROUND(O19,0.25) -> 23.25 | U19: =MROUND(P19,0.25) -> 24 | V19: =MROUND(Q19,0.25) -> 25 | W19: =MROUND(R19,0.25) -> 25.75
A20: CABBAGE, DICED ZESTOS (20# CASE) | B20: ZES | C20: Cabbage, Bag | D20: No | E20: Foodservice | F20: 4/5 NEW KRAFT | G20: 35 | H20: =VLOOKUP($C20,'Raw Cost'!$A$1:$B$484,2,FALSE)/G20 -> 0.48571429 | I20: =H20/16 -> 0.030357143 | J20: 20 | K20: 0.25 | L20: =VLOOKUP($F20,'Packaging Cost'!$A$1:$F$43,6,FALSE) -> 1.23 | M20: =IF($E20="Snakpak",(($J20*H20)+($K20*'Labor Cost'!$A$2)+L20)+2.25,($J20*H20)+($K20*'Labor Cost'!$A$2)+L20+1) -> 17.819286 | N20: =IF($D20="No",$M20*1.25,($M20*1.25)+15) -> 22.274107 | O20: =IF($D20="No",$M20*1.3,($M20*1.3)+15) -> 23.165071 | P20: =IF($D20="No",$M20*1.35,($M20*1.35)+15) -> 24.056036 | Q20: =IF($D20="No",$M20*1.4,($M20*1.4)+15) -> 24.947 | R20: =IF($D20="No",$M20*1.45,($M20*1.45)+15) -> 25.837964 | S20: =MROUND(N20,0.25) -> 22.25 | T20: =MROUND(O20,0.25) -> 23.25 | U20: =MROUND(P20,0.25) -> 24 | V20: =MROUND(Q20,0.25) -> 25 | W20: =MROUND(R20,0.25) -> 25.75
A21: CABBAGE, SHRED RED (20# CASE) | B21: SR | C21: Cabbage, Red | D21: No | E21: Foodservice | F21: 4/5 NEW KRAFT | G21: 35 | H21: =VLOOKUP($C21,'Raw Cost'!$A$1:$B$484,2,FALSE)/G21 -> 0.71428571 | I21: =H21/16 -> 0.044642857 | J21: 20 | K21: 0.25 | L21: =VLOOKUP($F21,'Packaging Cost'!$A$1:$F$43,6,FALSE) -> 1.23 | M21: =IF($E21="Snakpak",(($J21*H21)+($K21*'Labor Cost'!$A$2)+L21)+2.25,($J21*H21)+($K21*'Labor Cost'!$A$2)+L21+1) -> 22.390714 | N21: =IF($D21="No",$M21*1.25,($M21*1.25)+15) -> 27.988393 | O21: =IF($D21="No",$M21*1.3,($M21*1.3)+15) -> 29.107929 | P21: =IF($D21="No",$M21*1.35,($M21*1.35)+15) -> 30.227464 | Q21: =IF($D21="No",$M21*1.4,($M21*1.4)+15) -> 31.347 | R21: =IF($D21="No",$M21*1.45,($M21*1.45)+15) -> 32.466536 | S21: =MROUND(N21,0.25) -> 28 | T21: =MROUND(O21,0.25) -> 29 | U21: =MROUND(P21,0.25) -> 30.25 | V21: =MROUND(Q21,0.25) -> 31.25 | W21: =MROUND(R21,0.25) -> 32.5
A22: CANTALOUPE CUBED (5# CASE) | B22: CANC | C22: Canteloupes | D22: No | E22: Foodservice | F22: 1/5 FRUIT TRAY | G22: 18 | H22: =VLOOKUP($C22,'Raw Cost'!$A$1:$B$484,2,FALSE)/G22 -> 1.1111111 | I22: =H22/16 -> 0.069444444 | J22: 5 | K22: 0.25 | L22: =VLOOKUP($F22,'Packaging Cost'!$A$1:$F$43,6,FALSE) -> 1.76 | M22: =IF($E22="Snakpak",(($J22*H22)+($K22*'Labor Cost'!$A$2)+L22)+2.25,($J22*H22)+($K22*'Labor Cost'!$A$2)+L22+1) -> 14.190556 | N22: =IF($D22="No",$M22*1.25,($M22*1.25)+15) -> 17.738194 | O22: =IF($D22="No",$M22*1.3,($M22*1.3)+15) -> 18.447722 | P22: =IF($D22="No",$M22*1.35,($M22*1.35)+15) -> 19.15725 | Q22: =IF($D22="No",$M22*1.4,($M22*1.4)+15) -> 19.866778 | R22: =IF($D22="No",$M22*1.45,($M22*1.45)+15) -> 20.576306 | S22: =MROUND(N22,0.25) -> 17.75 | T22: =MROUND(O22,0.25) -> 18.5 | U22: =MROUND(P22,0.25) -> 19.25 | V22: =MROUND(Q22,0.25) -> 19.75 | W22: =MROUND(R22,0.25) -> 20.5
A23: CANTALOUPE, HALVED (5#CASE) | B23: CANH | C23: Canteloupes | D23: No | E23: Foodservice | F23: 1/5 FRUIT TRAY | G23: 18 | H23: =VLOOKUP($C23,'Raw Cost'!$A$1:$B$484,2,FALSE)/G23 -> 1.1111111 | I23: =H23/16 -> 0.069444444 | J23: 5 | K23: 0.25 | L23: =VLOOKUP($F23,'Packaging Cost'!$A$1:$F$43,6,FALSE) -> 1.76 | M23: =IF($E23="Snakpak",(($J23*H23)+($K23*'Labor Cost'!$A$2)+L23)+2.25,($J23*H23)+($K23*'Labor Cost'!$A$2)+L23+1) -> 14.190556 | N23: =IF($D23="No",$M23*1.25,($M23*1.25)+15) -> 17.738194 | O23: =IF($D23="No",$M23*1.3,($M23*1.3)+15) -> 18.447722 | P23: =IF($D23="No",$M23*1.35,($M23*1.35)+15) -> 19.15725 | Q23: =IF($D23="No",$M23*1.4,($M23*1.4)+15) -> 19.866778 | R23: =IF($D23="No",$M23*1.45,($M23*1.45)+15) -> 20.576306 | S23: =MROUND(N23,0.25) -> 17.75 | T23: =MROUND(O23,0.25) -> 18.5 | U23: =MROUND(P23,0.25) -> 19.25 | V23: =MROUND(Q23,0.25) -> 19.75 | W23: =MROUND(R23,0.25) -> 20.5
A24: CANTALOUPE, SLICED (10# CASE) | B24: CANSL | C24: Canteloupes | D24: No | E24: Foodservice | F24: 2/5 FRUIT TRAY | G24: 18 | H24: =VLOOKUP($C24,'Raw Cost'!$A$1:$B$484,2,FALSE)/G24 -> 1.1111111 | I24: =H24/16 -> 0.069444444 | J24: 10 | K24: 0.25 | L24: =VLOOKUP($F24,'Packaging Cost'!$A$1:$F$43,6,FALSE) -> 3.22 | M24: =IF($E24="Snakpak",(($J24*H24)+($K24*'Labor Cost'!$A$2)+L24)+2.25,($J24*H24)+($K24*'Labor Cost'!$A$2)+L24+1) -> 21.206111 | N24: =IF($D24="No",$M24*1.25,($M24*1.25)+15) -> 26.507639 | O24: =IF($D24="No",$M24*1.3,($M24*1.3)+15) -> 27.567944 | P24: =IF($D24="No",$M24*1.35,($M24*1.35)+15) -> 28.62825 | Q24: =IF($D24="No",$M24*1.4,($M24*1.4)+15) -> 29.688556 | R24: =IF($D24="No",$M24*1.45,($M24*1.45)+15) -> 30.748861 | S24: =MROUND(N24,0.25) -> 26.5 | T24: =MROUND(O24,0.25) -> 27.5 | U24: =MROUND(P24,0.25) -> 28.75 | V24: =MROUND(Q24,0.25) -> 29.75 | W24: =MROUND(R24,0.25) -> 30.75
A25: CARROT STICKS (10# CASE) | B25: CARST10 | C25: Carrots,50# | D25: No | E25: Foodservice | F25: 2/5 TUB | G25: 35 | H25: =VLOOKUP($C25,'Raw Cost'!$A$1:$B$484,2,FALSE)/G25 -> 0.85714286 | I25: =H25/16 -> 0.053571429 | J25: 10 | K25: 0.25 | L25: =VLOOKUP($F25,'Packaging Cost'!$A$1:$F$43,6,FALSE) -> 0.9 | M25: =IF($E25="Snakpak",(($J25*H25)+($K25*'Labor Cost'!$A$2)+L25)+2.25,($J25*H25)+($K25*'Labor Cost'!$A$2)+L25+1) -> 16.346429 | N25: =IF($D25="No",$M25*1.25,($M25*1.25)+15) -> 20.433036 | O25: =IF($D25="No",$M25*1.3,($M25*1.3)+15) -> 21.250357 | P25: =IF($D25="No",$M25*1.35,($M25*1.35)+15) -> 22.067679 | Q25: =IF($D25="No",$M25*1.4,($M25*1.4)+15) -> 22.885 | R25: =IF($D25="No",$M25*1.45,($M25*1.45)+15) -> 23.702321 | S25: =MROUND(N25,0.25) -> 20.5 | T25: =MROUND(O25,0.25) -> 21.25 | U25: =MROUND(P25,0.25) -> 22 | V25: =MROUND(Q25,0.25) -> 23 | W25: =MROUND(R25,0.25) -> 23.75
A26: CARROT STICKS (20# CASE) | B26: CARST | C26: Carrots,50# | D26: No | E26: Foodservice | F26: 4/5 NEW KRAFT | G26: 35 | H26: =VLOOKUP($C26,'Raw Cost'!$A$1:$B$484,2,FALSE)/G26 -> 0.85714286 | I26: =H26/16 -> 0.053571429 | J26: 20 | K26: 0.25 | L26: =VLOOKUP($F26,'Packaging Cost'!$A$1:$F$43,6,FALSE) -> 1.23 | M26: =IF($E26="Snakpak",(($J26*H26)+($K26*'Labor Cost'!$A$2)+L26)+2.25,($J26*H26)+($K26*'Labor Cost'!$A$2)+L26+2) -> 26.247857 | N26: =IF($D26="No",$M26*1.25,($M26*1.25)+15) -> 32.809821 | O26: =IF($D26="No",$M26*1.3,($M26*1.3)+15) -> 34.122214 | P26: =IF($D26="No",$M26*1.35,($M26*1.35)+15) -> 35.434607 | Q26: =IF($D26="No",$M26*1.4,($M26*1.4)+15) -> 36.747 | R26: =IF($D26="No",$M26*1.45,($M26*1.45)+15) -> 38.059393 | S26: =MROUND(N26,0.25) -> 32.75 | T26: =MROUND(O26,0.25) -> 34 | U26: =MROUND(P26,0.25) -> 35.5 | V26: =MROUND(Q26,0.25) -> 36.75 | W26: =MROUND(R26,0.25) -> 38
A27: CARROT STICKS MCENTIRE (4# CASE) | B27: CARST10 | C27: Carrots,50# | D27: No | E27: Foodservice | F27: 1/5 TUB | G27: 35 | H27: =VLOOKUP($C27,'Raw Cost'!$A$1:$B$484,2,FALSE)/G27 -> 0.85714286 | I27: =H27/16 -> 0.053571429 | J27: 4 | K27: 0.25 | L27: =VLOOKUP($F27,'Packaging Cost'!$A$1:$F$43,6,FALSE) -> 0.59 | M27: =IF($E27="Snakpak",(($J27*H27)+($K27*'Labor Cost'!$A$2)+L27)+2.25,($J27*H27)+($K27*'Labor Cost'!$A$2)+L27+1) -> 10.893571 | N27: =IF($D27="No",$M27*1.25,($M27*1.25)+15) -> 13.616964 | O27: =IF($D27="No",$M27*1.3,($M27*1.3)+15) -> 14.161643 | P27: =IF($D27="No",$M27*1.35,($M27*1.35)+15) -> 14.706321 | Q27: =IF($D27="No",$M27*1.4,($M27*1.4)+15) -> 15.251 | R27: =IF($D27="No",$M27*1.45,($M27*1.45)+15) -> 15.795679 | S27: =MROUND(N27,0.25) -> 13.5 | T27: =MROUND(O27,0.25) -> 14.25 | U27: =MROUND(P27,0.25) -> 14.75 | V27: =MROUND(Q27,0.25) -> 15.25 | W27: =MROUND(R27,0.25) -> 15.75
A28: CARROT, STICKS (BWW)(4 X 5# CASE) | B28: CARSTBW | C28: Carrots,50# | D28: No | E28: Foodservice | F28: 4/5 NEW KRAFT | G28: 35 | H28: =VLOOKUP($C28,'Raw Cost'!$A$1:$B$484,2,FALSE)/G28 -> 0.85714286 | I28: =H28/16 -> 0.053571429 | J28: 20 | K28: 0.25 | L28: =VLOOKUP($F28,'Packaging Cost'!$A$1:$F$43,6,FALSE) -> 1.23 | M28: =IF($E28="Snakpak",(($J28*H28)+($K28*'Labor Cost'!$A$2)+L28)+2.25,($J28*H28)+($K28*'Labor Cost'!$A$2)+L28+1) -> 25.247857 | N28: =IF($D28="No",$M28*1.25,($M28*1.25)+15) -> 31.559821 | O28: =IF($D28="No",$M28*1.3,($M28*1.3)+15) -> 32.822214 | P28: =IF($D28="No",$M28*1.35,($M28*1.35)+15) -> 34.084607 | Q28: =IF($D28="No",$M28*1.4,($M28*1.4)+15) -> 35.347 | R28: =IF($D28="No",$M28*1.45,($M28*1.45)+15) -> 36.609393 | S28: =MROUND(N28,0.25) -> 31.5 | T28: =MROUND(O28,0.25) -> 32.75 | U28: =MROUND(P28,0.25) -> 34 | V28: =MROUND(Q28,0.25) -> 35.25 | W28: =MROUND(R28,0.25) -> 36.5
A29: CARROTS, COINS (2X5# CASE) | B29: CCCAR10 | C29: Carrots,50# | D29: No | E29: Foodservice | F29: 2/5 TUB | G29: 35 | H29: =VLOOKUP($C29,'Raw Cost'!$A$1:$B$484,2,FALSE)/G29 -> 0.85714286 | I29: =H29/16 -> 0.053571429 | J29: 10 | K29: 0.25 | L29: =VLOOKUP($F29,'Packaging Cost'!$A$1:$F$43,6,FALSE) -> 0.9 | M29: =IF($E29="Snakpak",(($J29*H29)+($K29*'Labor Cost'!$A$2)+L29)+2.25,($J29*H29)+($K29*'Labor Cost'!$A$2)+L29+1) -> 16.346429 | N29: =IF($D29="No",$M29*1.25,($M29*1.25)+15) -> 20.433036 | O29: =IF($D29="No",$M29*1.3,($M29*1.3)+15) -> 21.250357 | P29: =IF($D29="No",$M29*1.35,($M29*1.35)+15) -> 22.067679 | Q29: =IF($D29="No",$M29*1.4,($M29*1.4)+15) -> 22.885 | R29: =IF($D29="No",$M29*1.45,($M29*1.45)+15) -> 23.702321 | S29: =MROUND(N29,0.25) -> 20.5 | T29: =MROUND(O29,0.25) -> 21.25 | U29: =MROUND(P29,0.25) -> 22 | V29: =MROUND(Q29,0.25) -> 23 | W29: =MROUND(R29,0.25) -> 23.75
A30: CARROTS, COINS (4X5# CASE) | B30: CCCAR | C30: Carrots,50# | D30: No | E30: Foodservice | F30: 4/5 NEW KRAFT | G30: 35 | H30: =VLOOKUP($C30,'Raw Cost'!$A$1:$B$484,2,FALSE)/G30 -> 0.85714286 | I30: =H30/16 -> 0.053571429 | J30: 20 | K30: 0.25 | L30: =VLOOKUP($F30,'Packaging Cost'!$A$1:$F$43,6,FALSE) -> 1.23 | M30: =IF($E30="Snakpak",(($J30*H30)+($K30*'Labor Cost'!$A$2)+L30)+2.25,($J30*H30)+($K30*'Labor Cost'!$A$2)+L30+1) -> 25.247857 | N30: =IF($D30="No",$M30*1.25,($M30*1.25)+15) -> 31.559821 | O30: =IF($D30="No",$M30*1.3,($M30*1.3)+15) -> 32.822214 | P30: =IF($D30="No",$M30*1.35,($M30*1.35)+15) -> 34.084607 | Q30: =IF($D30="No",$M30*1.4,($M30*1.4)+15) -> 35.347 | R30: =IF($D30="No",$M30*1.45,($M30*1.45)+15) -> 36.609393 | S30: =MROUND(N30,0.25) -> 31.5 | T30: =MROUND(O30,0.25) -> 32.75 | U30: =MROUND(P30,0.25) -> 34 | V30: =MROUND(Q30,0.25) -> 35.25 | W30: =MROUND(R30,0.25) -> 36.5
A31: CARROTS, DICED (2X5# CASE) | B31: DCAR10 | C31: Carrots,50# | D31: No | E31: Foodservice | F31: 2/5 TUB | G31: 35 | H31: =VLOOKUP($C31,'Raw Cost'!$A$1:$B$484,2,FALSE)/G31 -> 0.85714286 | I31: =H31/16 -> 0.053571429 | J31: 10 | K31: 0.25 | L31: =VLOOKUP($F31,'Packaging Cost'!$A$1:$F$43,6,FALSE) -> 0.9 | M31: =IF($E31="Snakpak",(($J31*H31)+($K31*'Labor Cost'!$A$2)+L31)+2.25,($J31*H31)+($K31*'Labor Cost'!$A$2)+L31+1) -> 16.346429 | N31: =IF($D31="No",$M31*1.25,($M31*1.25)+15) -> 20.433036 | O31: =IF($D31="No",$M31*1.3,($M31*1.3)+15) -> 21.250357 | P31: =IF($D31="No",$M31*1.35,($M31*1.35)+15) -> 22.067679 | Q31: =IF($D31="No",$M31*1.4,($M31*1.4)+15) -> 22.885 | R31: =IF($D31="No",$M31*1.45,($M31*1.45)+15) -> 23.702321 | S31: =MROUND(N31,0.25) -> 20.5 | T31: =MROUND(O31,0.25) -> 21.25 | U31: =MROUND(P31,0.25) -> 22 | V31: =MROUND(Q31,0.25) -> 23 | W31: =MROUND(R31,0.25) -> 23.75
A32: CARROTS, DICED (4X5# CASE) | B32: CARD | C32: Carrots,50# | D32: No | E32: Foodservice | F32: 4/5 NEW KRAFT | G32: 35 | H32: =VLOOKUP($C32,'Raw Cost'!$A$1:$B$484,2,FALSE)/G32 -> 0.85714286 | I32: =H32/16 -> 0.053571429 | J32: 20 | K32: 0.25 | L32: =VLOOKUP($F32,'Packaging Cost'!$A$1:$F$43,6,FALSE) -> 1.23 | M32: =IF($E32="Snakpak",(($J32*H32)+($K32*'Labor Cost'!$A$2)+L32)+2.25,($J32*H32)+($K32*'Labor Cost'!$A$2)+L32+1) -> 25.247857 | N32: =IF($D32="No",$M32*1.25,($M32*1.25)+15) -> 31.559821 | O32: =IF($D32="No",$M32*1.3,($M32*1.3)+15) -> 32.822214 | P32: =IF($D32="No",$M32*1.35,($M32*1.35)+15) -> 34.084607 | Q32: =IF($D32="No",$M32*1.4,($M32*1.4)+15) -> 35.347 | R32: =IF($D32="No",$M32*1.45,($M32*1.45)+15) -> 36.609393 | S32: =MROUND(N32,0.25) -> 31.5 | T32: =MROUND(O32,0.25) -> 32.75 | U32: =MROUND(P32,0.25) -> 34 | V32: =MROUND(Q32,0.25) -> 35.25 | W32: =MROUND(R32,0.25) -> 36.5
A33: CARROTS, PEELED (4X5# CASE) | B33: PCAR | C33: Carrots,50# | D33: No | E33: Foodservice | F33: 4/5 NEW KRAFT | G33: 38 | H33: =VLOOKUP($C33,'Raw Cost'!$A$1:$B$484,2,FALSE)/G33 -> 0.78947368 | I33: =H33/16 -> 0.049342105 | J33: 20 | K33: 0.25 | L33: =VLOOKUP($F33,'Packaging Cost'!$A$1:$F$43,6,FALSE) -> 1.23 | M33: =IF($E33="Snakpak",(($J33*H33)+($K33*'Labor Cost'!$A$2)+L33)+2.25,($J33*H33)+($K33*'Labor Cost'!$A$2)+L33+1) -> 23.894474 | N33: =IF($D33="No",$M33*1.25,($M33*1.25)+15) -> 29.868092 | O33: =IF($D33="No",$M33*1.3,($M33*1.3)+15) -> 31.062816 | P33: =IF($D33="No",$M33*1.35,($M33*1.35)+15) -> 32.257539 | Q33: =IF($D33="No",$M33*1.4,($M33*1.4)+15) -> 33.452263 | R33: =IF($D33="No",$M33*1.45,($M33*1.45)+15) -> 34.646987 | S33: =MROUND(N33,0.25) -> 29.75 | T33: =MROUND(O33,0.25) -> 31 | U33: =MROUND(P33,0.25) -> 32.25 | V33: =MROUND(Q33,0.25) -> 33.5 | W33: =MROUND(R33,0.25) -> 34.75
A34: CAULIFLOWER FLORETS (4X3# CASE) | B34: CFL | C34: Cauliflower | D34: No | E34: Foodservice | F34: 4/5 NEW KRAFT | G34: 16 | H34: =VLOOKUP($C34,'Raw Cost'!$A$1:$B$484,2,FALSE)/G34 -> 2.31875 | I34: =H34/16 -> 0.14492188 | J34: 12 | K34: 0.25 | L34: =VLOOKUP($F34,'Packaging Cost'!$A$1:$F$43,6,FALSE) -> 1.23 | M34: =IF($E34="Snakpak",(($J34*H34)+($K34*'Labor Cost'!$A$2)+L34)+2.25,($J34*H34)+($K34*'Labor Cost'!$A$2)+L34+1) -> 35.93 | N34: =IF($D34="No",$M34*1.25,($M34*1.25)+15) -> 44.9125 | O34: =IF($D34="No",$M34*1.3,($M34*1.3)+15) -> 46.709 | P34: =IF($D34="No",$M34*1.35,($M34*1.35)+15) -> 48.5055 | Q34: =IF($D34="No",$M34*1.4,($M34*1.4)+15) -> 50.302 | R34: =IF($D34="No",$M34*1.45,($M34*1.45)+15) -> 52.0985 | S34: =MROUND(N34,0.25) -> 45 | T34: =MROUND(O34,0.25) -> 46.75 | U34: =MROUND(P34,0.25) -> 48.5 | V34: =MROUND(Q34,0.25) -> 50.25 | W34: =MROUND(R34,0.25) -> 52
A35: CAULIFLOWER FLORETS MULTICOLOR (4X3# CASE) | B35: CFL | C35: Cauliflower Tri Color | D35: No | E35: Foodservice | F35: 4/3 TUB | G35: 4 | H35: =VLOOKUP($C35,'Raw Cost'!$A$1:$B$484,2,FALSE)/G35 -> 11 | I35: =H35/16 -> 0.6875 | J35: 12 | K35: 0.25 | L35: =VLOOKUP($F35,'Packaging Cost'!$A$1:$F$43,6,FALSE) -> 1.15 | M35: =IF($E35="Snakpak",(($J35*H35)+($K35*'Labor Cost'!$A$2)+L35)+2.25,($J35*H35)+($K35*'Labor Cost'!$A$2)+L35+1) -> 140.025 | N35: =IF($D35="No",$M35*1.25,($M35*1.25)+15) -> 175.03125 | O35: =IF($D35="No",$M35*1.3,($M35*1.3)+15) -> 182.0325 | P35: =IF($D35="No",$M35*1.35,($M35*1.35)+15) -> 189.03375 | Q35: =IF($D35="No",$M35*1.4,($M35*1.4)+15) -> 196.035 | R35: =IF($D35="No",$M35*1.45,($M35*1.45)+15) -> 203.03625 | S35: =MROUND(N35,0.25) -> 175 | T35: =MROUND(O35,0.25) -> 182 | U35: =MROUND(P35,0.25) -> 189 | V35: =MROUND(Q35,0.25) -> 196 | W35: =MROUND(R35,0.25) -> 203
A36: CELERY STICKS (4X5# CASE) | B36: CELST | C36: Celery 30 ct | D36: No | E36: Foodservice | F36: 4/5 NEW KRAFT | G36: 32 | H36: =VLOOKUP($C36,'Raw Cost'!$A$1:$B$484,2,FALSE)/G36 -> 0.9375 | I36: =H36/16 -> 0.05859375 | J36: 20 | K36: 0.25 | L36: =VLOOKUP($F36,'Packaging Cost'!$A$1:$F$43,6,FALSE) -> 1.23 | M36: =IF($E36="Snakpak",(($J36*H36)+($K36*'Labor Cost'!$A$2)+L36)+2.25,($J36*H36)+($K36*'Labor Cost'!$A$2)+L36+2) -> 27.855 | N36: =IF($D36="No",$M36*1.25,($M36*1.25)+15) -> 34.81875 | O36: =IF($D36="No",$M36*1.3,($M36*1.3)+15) -> 36.2115 | P36: =IF($D36="No",$M36*1.35,($M36*1.35)+15) -> 37.60425 | Q36: =IF($D36="No",$M36*1.4,($M36*1.4)+15) -> 38.997 | R36: =IF($D36="No",$M36*1.45,($M36*1.45)+15) -> 40.38975 | S36: =MROUND(N36,0.25) -> 34.75 | T36: =MROUND(O36,0.25) -> 36.25 | U36: =MROUND(P36,0.25) -> 37.5 | V36: =MROUND(Q36,0.25) -> 39 | W36: =MROUND(R36,0.25) -> 40.5
A37: CELERY, DICED (2X5# CASE) | B37: CELD10 | C37: Celery 30 ct | D37: No | E37: Foodservice | F37: 2/5 TUB | G37: 32 | H37: =VLOOKUP($C37,'Raw Cost'!$A$1:$B$484,2,FALSE)/G37 -> 0.9375 | I37: =H37/16 -> 0.05859375 | J37: 10 | K37: 0.25 | L37: =VLOOKUP($F37,'Packaging Cost'!$A$1:$F$43,6,FALSE) -> 0.9 | M37: =IF($E37="Snakpak",(($J37*H37)+($K37*'Labor Cost'!$A$2)+L37)+2.25,($J37*H37)+($K37*'Labor Cost'!$A$2)+L37+1) -> 17.15 | N37: =IF($D37="No",$M37*1.25,($M37*1.25)+15) -> 21.4375 | O37: =IF($D37="No",$M37*1.3,($M37*1.3)+15) -> 22.295 | P37: =IF($D37="No",$M37*1.35,($M37*1.35)+15) -> 23.1525 | Q37: =IF($D37="No",$M37*1.4,($M37*1.4)+15) -> 24.01 | R37: =IF($D37="No",$M37*1.45,($M37*1.45)+15) -> 24.8675 | S37: =MROUND(N37,0.25) -> 21.5 | T37: =MROUND(O37,0.25) -> 22.25 | U37: =MROUND(P37,0.25) -> 23.25 | V37: =MROUND(Q37,0.25) -> 24 | W37: =MROUND(R37,0.25) -> 24.75
A38: CELERY, DICED (4X5# CASE) | B38: CELD | C38: Celery 30 ct | D38: No | E38: Foodservice | F38: 4/5 NEW KRAFT | G38: 32 | H38: =VLOOKUP($C38,'Raw Cost'!$A$1:$B$484,2,FALSE)/G38 -> 0.9375 | I38: =H38/16 -> 0.05859375 | J38: 20 | K38: 0.25 | L38: =VLOOKUP($F38,'Packaging Cost'!$A$1:$F$43,6,FALSE) -> 1.23 | M38: =IF($E38="Snakpak",(($J38*H38)+($K38*'Labor Cost'!$A$2)+L38)+2.25,($J38*H38)+($K38*'Labor Cost'!$A$2)+L38+1) -> 26.855 | N38: =IF($D38="No",$M38*1.25,($M38*1.25)+15) -> 33.56875 | O38: =IF($D38="No",$M38*1.3,($M38*1.3)+15) -> 34.9115 | P38: =IF($D38="No",$M38*1.35,($M38*1.35)+15) -> 36.25425 | Q38: =IF($D38="No",$M38*1.4,($M38*1.4)+15) -> 37.597 | R38: =IF($D38="No",$M38*1.45,($M38*1.45)+15) -> 38.93975 | S38: =MROUND(N38,0.25) -> 33.5 | T38: =MROUND(O38,0.25) -> 35 | U38: =MROUND(P38,0.25) -> 36.25 | V38: =MROUND(Q38,0.25) -> 37.5 | W38: =MROUND(R38,0.25) -> 39
A39: CELERY, ROOT DICED (2X5# CASE) | B39: CELD | C39: Celery Root | D39: No | E39: Foodservice | F39: 2/5 TUB | G39: 20 | H39: =VLOOKUP($C39,'Raw Cost'!$A$1:$B$484,2,FALSE)/G39 -> 1.7 | I39: =H39/16 -> 0.10625 | J39: 10 | K39: 0.25 | L39: =VLOOKUP($F39,'Packaging Cost'!$A$1:$F$43,6,FALSE) -> 0.9 | M39: =IF($E39="Snakpak",(($J39*H39)+($K39*'Labor Cost'!$A$2)+L39)+2.25,($J39*H39)+($K39*'Labor Cost'!$A$2)+L39+1) -> 24.775 | N39: =IF($D39="No",$M39*1.25,($M39*1.25)+15) -> 30.96875 | O39: =IF($D39="No",$M39*1.3,($M39*1.3)+15) -> 32.2075 | P39: =IF($D39="No",$M39*1.35,($M39*1.35)+15) -> 33.44625 | Q39: =IF($D39="No",$M39*1.4,($M39*1.4)+15) -> 34.685 | R39: =IF($D39="No",$M39*1.45,($M39*1.45)+15) -> 35.92375 | S39: =MROUND(N39,0.25) -> 31 | T39: =MROUND(O39,0.25) -> 32.25 | U39: =MROUND(P39,0.25) -> 33.5 | V39: =MROUND(Q39,0.25) -> 34.75 | W39: =MROUND(R39,0.25) -> 36
A40: CELERY, SLICED (2X5# CASE) | B40: CELD | C40: Celery 30 ct | D40: No | E40: Foodservice | F40: 2/5 TUB | G40: 32 | H40: =VLOOKUP($C40,'Raw Cost'!$A$1:$B$484,2,FALSE)/G40 -> 0.9375 | I40: =H40/16 -> 0.05859375 | J40: 10 | K40: 0.25 | L40: =VLOOKUP($F40,'Packaging Cost'!$A$1:$F$43,6,FALSE) -> 0.9 | M40: =IF($E40="Snakpak",(($J40*H40)+($K40*'Labor Cost'!$A$2)+L40)+2.25,($J40*H40)+($K40*'Labor Cost'!$A$2)+L40+1) -> 17.15 | N40: =IF($D40="No",$M40*1.25,($M40*1.25)+15) -> 21.4375 | O40: =IF($D40="No",$M40*1.3,($M40*1.3)+15) -> 22.295 | P40: =IF($D40="No",$M40*1.35,($M40*1.35)+15) -> 23.1525 | Q40: =IF($D40="No",$M40*1.4,($M40*1.4)+15) -> 24.01 | R40: =IF($D40="No",$M40*1.45,($M40*1.45)+15) -> 24.8675 | S40: =MROUND(N40,0.25) -> 21.5 | T40: =MROUND(O40,0.25) -> 22.25 | U40: =MROUND(P40,0.25) -> 23.25 | V40: =MROUND(Q40,0.25) -> 24 | W40: =MROUND(R40,0.25) -> 24.75
...

Sheet NEW MARK UP LIST
A1: ITEM | B1: PRICE | C1: UNIT COST | D1: MARK UP $ | E1: PERCENTAGE
A2: ACORN SQUASH, DICED (4X5#CASE) | B2: 56.5 | C2: ='Master Item List'!M2 -> 34.105 | D2: =B2-C2 -> 22.395 | E2: =D2/C2 -> 0.65664859
A3: APPLE, GREEN DICED (4X5# CASE) | B3: 46.75 | C3: ='Master Item List'!M3 -> 35.681897 | D3: =B3-C3 -> 11.068103 | E3: =D3/C3 -> 0.31018821
A4: APPLE, GREEN WEDGES (10X1# CASE) | B4: 33.5 | C4: ='Master Item List'!M4 -> 24.648448 | D4: =B4-C4 -> 8.8515517 | E4: =D4/C4 -> 0.35911193
A5: APPLE, GREEN WEDGES (4 X 3) | B5: 31.25 | C5: ='Master Item List'!M5 -> 23.749138 | D5: =B5-C5 -> 7.5008621 | E5: =D5/C5 -> 0.31583724
A6: APPLE, RED DICED (4X5# CASE) | B6: 37.25 | C6: ='Master Item List'!M6 -> 40.509483 | D6: =B6-C6 -> -3.2594828 | E6: =D6/C6 -> -0.080462216
A7: APPLE, RED WEDGES (10X1#CASE) | B7: 29.25 | C7: ='Master Item List'!M7 -> 27.062241 | D7: =B7-C7 -> 2.1877586 | E7: =D7/C7 -> 0.080841738
A8: APPLE, RED WEDGES (4X3#CASE) | B8: 30.25 | C8: ='Master Item List'!M8 -> 28.22569 | D8: =B8-C8 -> 2.0243103 | E8: =D8/C8 -> 0.07171872
A9: BEETS, CANDY STRIPE DICED (2X5#CASE) | B9: 37.5 | C9: ='Master Item List'!M9 -> 27.219444 | D9: =B9-C9 -> 10.280556 | E9: =D9/C9 -> 0.3776916
A10: BEETS, DICED (2X5#CASE) | B10: 28.25 | C10: ='Master Item List'!M10 -> 17.775 | D10: =B10-C10 -> 10.475 | E10: =D10/C10 -> 0.58931083
A11: BEETS, GOLD DICED (2X5#CASE) | B11: 37.25 | C11: ='Master Item List'!M11 -> 26.663889 | D11: =B11-C11 -> 10.586111 | E11: =D11/C11 -> 0.39702052
A12: BOK CHOY, CHOPPED (4 X 5# CASE) | B12: 39 | C12: ='Master Item List'!M12 -> 37.298333 | D12: =B12-C12 -> 1.7016667 | E12: =D12/C12 -> 0.045623129
A13: BROCCOLI FLORETS (4X3# CASE) | B13: 32.5 | C13: ='Master Item List'!M13 -> 25.705 | D13: =B13-C13 -> 6.795 | E13: =D13/C13 -> 0.26434546
... A26: CARROT STICKS (20# CASE) | B26: 36.25 | C26: ='Master Item List'!M26 -> 26.247857 | D26: =B26-C26 -> 10.002143 | E26: =D26/C26 -> 0.38106512
A27: CARROT, STICKS (BWW)(4 X 5# CASE) | B27: 37.25 | C27: ='Master Item List'!M28 -> 25.247857 | D27: =B27-C27 -> 12.002143 | E27: =D27/C27 -> 0.47537273
A28: CARROTS, COINS (2X5# CASE) | B28: 23.5 | C28: ='Master Item List'!M29 -> 16.346429 | D28: =B28-C28 -> 7.1535714 | E28: =D28/C28 -> 0.4376229
A29: CARROTS, COINS (4X5# CASE) | B29: 35.75 | C29: ='Master Item List'!M30 -> 25.247857 | D29: =B29-C29 -> 10.502143 | E29: =D29/C29 -> 0.41596175
A30: CARROTS, DICED (2X5# CASE) | B30: 24.75 | C30: ='Master Item List'!M31 -> 16.346429 | D30: =B30-C30 -> 8.4035714 | E30: =D30/C30 -> 0.5140922
A31: CARROTS, DICED (4X5# CASE) | B31: 34.5 | C31: ='Master Item List'!M32 -> 25.247857 | D31: =B31-C31 -> 9.2521429 | E31: =D31/C31 -> 0.3664526
A32: CARROTS, PEELED (4X5# CASE) | B32: 34.25 | C32: ='Master Item List'!M33 -> 23.894474 | D32: =B32-C32 -> 10.355526 | E32: =D32/C32 -> 0.43338583
A33: CAULIFLOWER FLORETS (4X3# CASE) | B33: 46.75 | C33: ='Master Item List'!M34 -> 35.93 | D33: =B33-C33 -> 10.82 | E33: =D33/C33 -> 0.30114111
A34: CAULIFLOWER FLORETS MULTICOLOR (4X3# CASE) | C34: ='Master Item List'!M35 -> 140.025 | D34: =B34-C34 -> -140.025 | E34: =D34/C34 -> -1
A35: CELERY STICKS (4X5# CASE) | B35: 39.5 | C35: ='Master Item List'!M36 -> 27.855 | D35: =B35-C35 -> 11.645 | E35: =D35/C35 -> 0.4180578
A36: CELERY, DICED (2X5# CASE) | B36: 23 | C36: ='Master Item List'!M37 -> 17.15 | D36: =B36-C36 -> 5.85 | E36: =D36/C36 -> 0.34110787
A37: CELERY, DICED (4X5# CASE) | B37: 38.5 | C37: ='Master Item List'!M38 -> 26.855 | D37: =B37-C37 -> 11.645 | E37: =D37/C37 -> 0.43362502
A38: CELERY, ROOT DICED (2X5# CASE) | B38: 35 | C38: ='Master Item List'!M39 -> 24.775 | D38: =B38-C38 -> 10.225 | E38: =D38/C38 -> 0.41271443
A39: CELERY, SLICED (2X5# CASE) | B39: 27.25 | C39: ='Master Item List'!M40 -> 17.15 | D39: =B39-C39 -> 10.1 | E39: =D39/C39 -> 0.58892128
A40: CHAYOTE, SQUASH 2" MATCHSTICK (2X5# CASE) | B40: 60.25 | C40: ='Master Item List'!M41 -> 53.865 | D40: =B40-C40 -> 6.385 | E40: =D40/C40 -> 0.11853708
A41: CILANTRO, CLEAN & TRIM (4X1# CASE) | B41: 25 | C41: ='Master Item List'!M42 -> 15.161667 | D41: =B41-C41 -> 9.8383333 | E41: =D41/C41 -> 0.64889524
A42: COLESLAW, DICED (4X5# CASE) | B42: 18.5 | C42: ='Master Item List'!M43 -> 17.819286 | D42: =B42-C42 -> 0.68071429 | E42: =D42/C42 -> 0.038200986
A43: COLESLAW, FINE SHREDDED, (4X5# CASE) | B43: 18.5 | C43: ='Master Item List'!M44 -> 17.819286 | D43: =B43-C43 -> 0.68071429 | E43: =D43/C43 -> 0.038200986
A44: COLESLAW, SAVOY BLEND (2X5# CASE) | B44: 48.5 | C44: ='Master Item List'!M45 -> 37.108333 | D44: =B44-C44 -> 11.391667 | E44: =D44/C44 -> 0.30698406
A45: COLESLAW, SHREDDED MIX (4X5# CASE) | B45: 18.5 | C45: ='Master Item List'!M46 -> 17.819286 | D45: =B45-C45 -> 0.68071429 | E45: =D45/C45 -> 0.038200986
A46: COLLARDS, CLEANED/CUT (6X2# CASE) | B46: 29 | C46: ='Master Item List'!M47 -> 19.825 | D46: =B46-C46 -> 9.175 | E46: =D46/C46 -> 0.4627995
... A167: ZUCCHINI, SLICED (5# CASE) | B167: 18.25 | C167: ='Master Item List'!M168 -> 11.781667 | D167: =B167-C167 -> 6.4683333 | E167: =D167/C167 -> 0.54901683
C168: ='Master Item List'!M169 -> 0 | D168: =B168-C168 -> 0 | E168: =D168/C168 -> #DIV/0!
A169: SNACK PACKS | C169: ='Master Item List'!M170 -> 0 | D169: =B169-C169 -> 0 | E169: =D169/C169 -> #DIV/0!
A170: APPLE, CARROTS MIX (50 X 2oz) | B170: 32.25 | C170: ='Master Item List'!M171 -> 22.074138 | D170: =B170-C170 -> 10.175862 | E170: =D170/C170 -> 0.46098571
A171: APPLE, CARROTS MIX W/RANCH (50 X 2oz) | B171: 48.25 | C171: ='Master Item List'!M172 -> 22.074138 | D171: =B171-C171 -> 26.175862 | E171: =D171/C171 -> 1.1858158
A172: APPLE, CELERY MIX (50 X 2oz) | B172: 29.25 | C172: ='Master Item List'!M173 -> 19.752709 | D172: =B172-C172 -> 9.4972906 | E172: =D172/C172 -> 0.48080952
...

Sheet Combo Pricing
A1: Item Name | B1: Item 1 | C1: Base Product | D1: Item 2 | E1: Item 3 | F1: Combined Unit Cost | G1: 0.25 | H1: 0.3 | I1: 0.35 | J1: 0.4 | K1: 25% Markup | L1: 30% Markup | M1: 35% Markup | N1: 40% Markup
A2: APPLE / PEAR (50/2oz) | B2: APPLE, RED WEDGES (50 X 2oz) | E2: PEARS, WEDGED (50 X 2oz) | F2: =(VLOOKUP($B2,'Master Item List'!$A$1:$V$320,13,FALSE)+VLOOKUP($E2,'Master Item List'!$A$1:$V$320,13,FALSE))/2 -> 18.854801 | G2: =$F2*1.25 -> 23.568501 | H2: =$F2*1.3 -> 24.511241 | I2: =$F2*1.35 -> 25.453981 | J2: =$F2*1.4 -> 26.396721 | K2: =MROUND(G2,0.25)+2.25 -> 25.75 | L2: =MROUND(H2,0.25)+2.25 -> 26.75 | M2: =MROUND(I2,0.25)+2.25 -> 27.75 | N2: =MROUND(J2,0.25)+2.25 -> 28.75
A3: APPLE / PEAR (100/2oz) | B3: APPLE, RED WEDGES (50 X 2oz) | E3: PEARS, WEDGED (50 X 2oz) | F3: =(VLOOKUP($B3,'Master Item List'!$A$1:$V$320,13,FALSE)+VLOOKUP($E3,'Master Item List'!$A$1:$V$320,13,FALSE)) -> 37.709601 | G3: =$F3*1.25 -> 47.137002 | H3: =$F3*1.3 -> 49.022482 | I3: =$F3*1.35 -> 50.907962 | J3: =$F3*1.4 -> 52.793442 | K3: =MROUND(G3,0.25)+2.25 -> 49.5 | L3: =MROUND(H3,0.25)+2.25 -> 51.25 | M3: =MROUND(I3,0.25)+2.25 -> 53.25 | N3: =MROUND(J3,0.25)+2.25 -> 55
A4: APPLE / CARROT (50 X 2oz) | B4: APPLE, RED WEDGES (50 X 2oz) | E4: CARROTS, BABY, (50 X 2oz) | F4: =(VLOOKUP($B4,'Master Item List'!$A$1:$V$320,13,FALSE)+VLOOKUP($E4,'Master Item List'!$A$1:$V$320,13,FALSE))/2 -> #N/A | G4: =$F4*1.25 -> #N/A | H4: =$F4*1.3 -> #N/A | I4: =$F4*1.35 -> #N/A | J4: =$F4*1.4 -> #N/A | K4: =MROUND(G4,0.25)+2.25 -> #N/A | L4: =MROUND(H4,0.25)+2.25 -> #N/A | M4: =MROUND(I4,0.25)+2.25 -> #N/A | N4: =MROUND(J4,0.25)+2.25 -> #N/A
A5: APPLE / CELERY (50/2oz) | B5: APPLE, RED WEDGES (50 X 2oz) | E5: CELERY STICKS (50 X 2oz) | F5: =(VLOOKUP($B5,'Master Item List'!$A$1:$V$320,13,FALSE)+VLOOKUP($E5,'Master Item List'!$A$1:$V$320,13,FALSE))/2 -> 17.225894 | G5: =$F5*1.25 -> 21.532368 | H5: =$F5*1.3 -> 22.393663 | I5: =$F5*1.35 -> 23.254957 | J5: =$F5*1.4 -> 24.116252 | K5: =MROUND(G5,0.25)+2.25 -> 23.75 | L5: =MROUND(H5,0.25)+2.25 -> 24.75 | M5: =MROUND(I5,0.25)+2.25 -> 25.5 | N5: =MROUND(J5,0.25)+2.25 -> 26.25
A6: APPLE / RED GRAPE (50 X 2.3oz) | B6: APPLE, RED WEDGES (50 X 2oz) | E6: ='Master Item List'!A61 -> GRAPES, RED (5# CASE) | F6: =(VLOOKUP($B6,'Master Item List'!$A$1:$V$320,13,FALSE)+VLOOKUP($E6,'Master Item List'!$A$1:$V$320,13,FALSE)/2) -> 27.273803 | G6: =$F6*1.25 -> 34.092253 | H6: =$F6*1.3 -> 35.455943 | I6: =$F6*1.35 -> 36.819634 | J6: =$F6*1.4 -> 38.183324 | K6: =MROUND(G6,0.25)+2.25 -> 36.25 | L6: =MROUND(H6,0.25)+2.25 -> 37.75 | M6: =MROUND(I6,0.25)+2.25 -> 39 | N6: =MROUND(J6,0.25)+2.25 -> 40.5 | P6: BAD FORMULA - not 50/50, should be 85/15
A7: APPLE / TURNIP (50/2oz) | B7: APPLE, RED WEDGES (50 X 2oz) | E7: TURNIP STICKS (50 X 2oz) | F7: =(VLOOKUP($B7,'Master Item List'!$A$1:$V$320,13,FALSE)+VLOOKUP($E7,'Master Item List'!$A$1:$V$320,13,FALSE))/2 -> #N/A | G7: =$F7*1.25 -> #N/A | H7: =$F7*1.3 -> #N/A | I7: =$F7*1.35 -> #N/A | J7: =$F7*1.4 -> #N/A | K7: =MROUND(G7,0.25)+2.25 -> #N/A | L7: =MROUND(H7,0.25)+2.25 -> #N/A | M7: =MROUND(I7,0.25)+2.25 -> #N/A | N7: =MROUND(J7,0.25)+2.25 -> #N/A
A8: BROCCOLI / CAULIFLOWER (50 X 2oz) | B8: BROCCOLI FLORET (50 X 2oz) | E8: CAULIFLOWER FLORET (50 X 2oz) | F8: =(VLOOKUP($B8,'Master Item List'!$A$1:$V$320,13,FALSE)+VLOOKUP($E8,'Master Item List'!$A$1:$V$320,13,FALSE))/2 -> 22.273611 | G8: =$F8*1.25 -> 27.842014 | H8: =$F8*1.3 -> 28.955694 | I8: =$F8*1.35 -> 30.069375 | J8: =$F8*1.4 -> 31.183056 | K8: =MROUND(G8,0.25)+2.25 -> 30 | L8: =MROUND(H8,0.25)+2.25 -> 31.25 | M8: =MROUND(I8,0.25)+2.25 -> 32.25 | N8: =MROUND(J8,0.25)+2.25 -> 33.5
A9: BROCCOLI / GRAPE TOMATO (50 X 2oz) | B9: BROCCOLI FLORET (50 X 2oz) | E9: GRAPE TOMATO (50 X 2oz) | F9: =(VLOOKUP($B9,'Master Item List'!$A$1:$V$320,13,FALSE)+VLOOKUP($E9,'Master Item List'!$A$1:$V$320,13,FALSE))/2 -> 20.426797 | G9: =$F9*1.25 -> 25.533497 | H9: =$F9*1.3 -> 26.554837 | I9: =$F9*1.35 -> 27.576176 | J9: =$F9*1.4 -> 28.597516 | K9: =MROUND(G9,0.25)+2.25 -> 27.75 | L9: =MROUND(H9,0.25)+2.25 -> 28.75 | M9: =MROUND(I9,0.25)+2.25 -> 29.75 | N9: =MROUND(J9,0.25)+2.25 -> 30.75
A10: BROCCOLI / SUGAR SNAPS (50 X 2oz) | B10: BROCCOLI FLORET (50 X 2oz) | E10: ='Master Item List'!A309 -> RICE 50/6OZ | F10: =(VLOOKUP($B10,'Master Item List'!$A$1:$V$320,13,FALSE)+VLOOKUP($E10,'Master Item List'!$A$1:$V$320,13,FALSE))/2 -> 43.369444 | G10: =$F10*1.25 -> 54.211806 | H10: =$F10*1.3 -> 56.380278 | I10: =$F10*1.35 -> 58.54875 | J10: =$F10*1.4 -> 60.717222 | K10: =MROUND(G10,0.25)+2.25 -> 56.5 | L10: =MROUND(H10,0.25)+2.25 -> 58.75 | M10: =MROUND(I10,0.25)+2.25 -> 60.75 | N10: =MROUND(J10,0.25)+2.25 -> 63
A11: CANTALOUPE / GRAPES (50 X 2.7oz) | B11: CANTALOUPE, CUBED (50 X 2.7oz) | E11: ='Master Item List'!A61 -> GRAPES, RED (5# CASE) | F11: =(VLOOKUP($B11,'Master Item List'!$A$1:$V$320,13,FALSE)+VLOOKUP($E11,'Master Item List'!$A$1:$V$320,13,FALSE)) -> 40.40719 | G11: =$F11*1.25 -> 50.508987 | H11: =$F11*1.3 -> 52.529346 | I11: =$F11*1.35 -> 54.549706 | J11: =$F11*1.4 -> 56.570065 | K11: =MROUND(G11,0.25)+2.25 -> 52.75 | L11: =MROUND(H11,0.25)+2.25 -> 54.75 | M11: =MROUND(I11,0.25)+2.25 -> 56.75 | N11: =MROUND(J11,0.25)+2.25 -> 58.75
A12: CANTALOUPE / HONEYDEW (50 X 2.7oz) | B12: CANTALOUPE, CUBED (50 X 2.7oz) | E12: HONEYDEW, CUBED, (50 X 2.7oz) | F12: =(VLOOKUP($B12,'Master Item List'!$A$1:$V$320,13,FALSE)+VLOOKUP($E12,'Master Item List'!$A$1:$V$320,13,FALSE))/2 -> 23.239373 | G12: =$F12*1.25 -> 29.049216 | H12: =$F12*1.3 -> 30.211184 | I12: =$F12*1.35 -> 31.373153 | J12: =$F12*1.4 -> 32.535122 | K12: =MROUND(G12,0.25)+2.25 -> 31.25 | L12: =MROUND(H12,0.25)+2.25 -> 32.5 | M12: =MROUND(I12,0.25)+2.25 -> 33.5 | N12: =MROUND(J12,0.25)+2.25 -> 34.75
A13: CANTALOUPE / PINEAPPLES (50 X 2.3oz) | B13: CANTALOUPE, CUBED (50 X 2.7oz) | E13: PINEAPPLE (50 X 2.3oz) | F13: =(VLOOKUP($B13,'Master Item List'!$A$1:$V$320,13,FALSE)+VLOOKUP($E13,'Master Item List'!$A$1:$V$320,13,FALSE))/2 -> 22.491811 | G13: =$F13*1.25 -> 28.114764 | H13: =$F13*1.3 -> 29.239354 | I13: =$F13*1.35 -> 30.363945 | J13: =$F13*1.4 -> 31.488536 | K13: =MROUND(G13,0.25)+2.25 -> 30.25 | L13: =MROUND(H13,0.25)+2.25 -> 31.5 | M13: =MROUND(I13,0.25)+2.25 -> 32.5 | N13: =MROUND(J13,0.25)+2.25 -> 33.75
A14: CARROT / BROCCOLI (50 X 2oz) | B14: CARROTS, BABY, (50 X 2oz) | E14: BROCCOLI FLORET (50 X 2oz) | F14: =(VLOOKUP($B14,'Master Item List'!$A$1:$V$320,13,FALSE)+VLOOKUP($E14,'Master Item List'!$A$1:$V$320,13,FALSE))/2 -> #N/A | G14: =$F14*1.25 -> #N/A | H14: =$F14*1.3 -> #N/A | I14: =$F14*1.35 -> #N/A | J14: =$F14*1.4 -> #N/A | K14: =MROUND(G14,0.25)+2.25 -> #N/A | L14: =MROUND(H14,0.25)+2.25 -> #N/A | M14: =MROUND(I14,0.25)+2.25 -> #N/A | N14: =MROUND(J14,0.25)+2.25 -> #N/A
A15: CARROT / CELERY (50 X 2oz) | B15: CARROTS, BABY, (50 X 2oz) | E15: CELERY STICKS (50 X 2oz) | F15: =(VLOOKUP($B15,'Master Item List'!$A$1:$V$320,13,FALSE)+VLOOKUP($E15,'Master Item List'!$A$1:$V$320,13,FALSE))/2 -> #N/A | G15: =$F15*1.25 -> #N/A | H15: =$F15*1.3 -> #N/A | I15: =$F15*1.35 -> #N/A | J15: =$F15*1.4 -> #N/A | K15: =MROUND(G15,0.25)+2.25 -> #N/A | L15: =MROUND(H15,0.25)+2.25 -> #N/A | M15: =MROUND(I15,0.25)+2.25 -> #N/A | N15: =MROUND(J15,0.25)+2.25 -> #N/A
A16: CARROT / GRAPE TOMATO (50 X 2oz) | B16: CARROTS, BABY, (50 X 2oz) | E16: GRAPE TOMATO (50 X 2oz) | F16: =(VLOOKUP($B16,'Master Item List'!$A$1:$V$320,13,FALSE)+VLOOKUP($E16,'Master Item List'!$A$1:$V$320,13,FALSE))/2 -> #N/A | G16: =$F16*1.25 -> #N/A | H16: =$F16*1.3 -> #N/A | I16: =$F16*1.35 -> #N/A | J16: =$F16*1.4 -> #N/A | K16: =MROUND(G16,0.25)+2.25 -> #N/A | L16: =MROUND(H16,0.25)+2.25 -> #N/A | M16: =MROUND(I16,0.25)+2.25 -> #N/A | N16: =MROUND(J16,0.25)+2.25 -> #N/A
A17: CARROT / PEARS (50 X 2oz) | B17: CARROTS, BABY, (50 X 2oz) | E17: PEARS, WEDGED (50 X 2oz) | F17: =(VLOOKUP($B17,'Master Item List'!$A$1:$V$320,13,FALSE)+VLOOKUP($E17,'Master Item List'!$A$1:$V$320,13,FALSE))/2 -> #N/A | G17: =$F17*1.25 -> #N/A | H17: =$F17*1.3 -> #N/A | I17: =$F17*1.35 -> #N/A | J17: =$F17*1.4 -> #N/A | K17: =MROUND(G17,0.25)+2.25 -> #N/A | L17: =MROUND(H17,0.25)+2.25 -> #N/A | M17: =MROUND(I17,0.25)+2.25 -> #N/A | N17: =MROUND(J17,0.25)+2.25 -> #N/A
A18: CARROT / SUGAR SNAPS (50 X 2oz) | B18: CARROTS, BABY, (50 X 2oz) | E18: ='Master Item List'!A309 -> RICE 50/6OZ | F18: =(VLOOKUP($B18,'Master Item List'!$A$1:$V$320,13,FALSE)+VLOOKUP($E18,'Master Item List'!$A$1:$V$320,13,FALSE))/2 -> #N/A | G18: =$F18*1.25 -> #N/A | H18: =$F18*1.3 -> #N/A | I18: =$F18*1.35 -> #N/A | J18: =$F18*1.4 -> #N/A | K18: =MROUND(G18,0.25)+2.25 -> #N/A | L18: =MROUND(H18,0.25)+2.25 -> #N/A | M18: =MROUND(I18,0.25)+2.25 -> #N/A | N18: =MROUND(J18,0.25)+2.25 -> #N/A
A19: CAULIFLOWER / GRAPE TOMATO (50 X 2oz) | B19: CAULIFLOWER FLORET (50 X 2oz) | E19: GRAPE TOMATO (50 X 2oz) | F19: =(VLOOKUP($B19,'Master Item List'!$A$1:$V$320,13,FALSE)+VLOOKUP($E19,'Master Item List'!$A$1:$V$320,13,FALSE))/2 -> 24.33652 | G19: =$F19*1.25 -> 30.42065 | H19: =$F19*1.3 -> 31.637475 | I19: =$F19*1.35 -> 32.854301 | J19: =$F19*1.4 -> 34.071127 | K19: =MROUND(G19,0.25)+2.25 -> 32.75 | L19: =MROUND(H19,0.25)+2.25 -> 34 | M19: =MROUND(I19,0.25)+2.25 -> 35 | N19: =MROUND(J19,0.25)+2.25 -> 36.25
A20: CELERY / GRAPE TOMATOES (50 X 2oz) | B20: CELERY STICKS (50 X 2oz) | E20: GRAPE TOMATO (50 X 2oz) | F20: =(VLOOKUP($B20,'Master Item List'!$A$1:$V$320,13,FALSE)+VLOOKUP($E20,'Master Item List'!$A$1:$V$320,13,FALSE))/2 -> 19.77204 | G20: =$F20*1.25 -> 24.715051 | H20: =$F20*1.3 -> 25.703653 | I20: =$F20*1.35 -> 26.692255 | J20: =$F20*1.4 -> 27.680857 | K20: =MROUND(G20,0.25)+2.25 -> 27 | L20: =MROUND(H20,0.25)+2.25 -> 28 | M20: =MROUND(I20,0.25)+2.25 -> 29 | N20: =MROUND(J20,0.25)+2.25 -> 30
A21: CELERY / PEARS (50 X 2oz) | B21: CELERY STICKS (50 X 2oz) | E21: PEARS, WEDGED (50 X 2oz) | F21: =(VLOOKUP($B21,'Master Item List'!$A$1:$V$320,13,FALSE)+VLOOKUP($E21,'Master Item List'!$A$1:$V$320,13,FALSE))/2 -> 18.683281 | G21: =$F21*1.25 -> 23.354102 | H21: =$F21*1.3 -> 24.288266 | I21: =$F21*1.35 -> 25.22243 | J21: =$F21*1.4 -> 26.156594 | K21: =MROUND(G21,0.25)+2.25 -> 25.5 | L21: =MROUND(H21,0.25)+2.25 -> 26.5 | M21: =MROUND(I21,0.25)+2.25 -> 27.5 | N21: =MROUND(J21,0.25)+2.25 -> 28.5
A22: CELERY / RED GRAPES (50 X 2.5oz) | B22: CELERY STICKS (50 X 2oz) | E22: ='Master Item List'!A61 -> GRAPES, RED (5# CASE) | F22: =(VLOOKUP($B22,'Master Item List'!$A$1:$V$320,13,FALSE)+VLOOKUP($E22,'Master Item List'!$A$1:$V$320,13,FALSE)) -> 36.807153 | G22: =$F22*1.25 -> 46.008941 | H22: =$F22*1.3 -> 47.849299 | I22: =$F22*1.35 -> 49.689656 | J22: =$F22*1.4 -> 51.530014 | K22: =MROUND(G22,0.25)+2.25 -> 48.25 | L22: =MROUND(H22,0.25)+2.25 -> 50 | M22: =MROUND(I22,0.25)+2.25 -> 52 | N22: =MROUND(J22,0.25)+2.25 -> 53.75
A23: CUCUMBER / PINEAPPLE (50 X 2.3oz) | B23: CUCUMBER, COINS (50 X 2oz) | E23: PINEAPPLE (50 X 2.3oz) | F23: =(VLOOKUP($B23,'Master Item List'!$A$1:$V$320,13,FALSE)+VLOOKUP($E23,'Master Item List'!$A$1:$V$320,13,FALSE))/2 -> 21.589605 | G23: =$F23*1.25 -> 26.987007 | H23: =$F23*1.3 -> 28.066487 | I23: =$F23*1.35 -> 29.145967 | J23: =$F23*1.4 -> 30.225447 | K23: =MROUND(G23,0.25)+2.25 -> 29.25 | L23: =MROUND(H23,0.25)+2.25 -> 30.25 | M23: =MROUND(I23,0.25)+2.25 -> 31.5 | N23: =MROUND(J23,0.25)+2.25 -> 32.5
A24: GRAPES / PINEAPPLES (50 X 2.3oz) | B24: ='Master Item List'!M61 -> 19.752778 | E24: ='Master Item List'!M295 -> 20.490625 | F24: =B24+E24 -> 40.243403 | G24: =$F24*1.25 -> 50.304253 | H24: =$F24*1.3 -> 52.316424 | I24: =$F24*1.35 -> 54.328594 | J24: =$F24*1.4 -> 56.340764 | K24: =MROUND(G24,0.25)+2.25 -> 52.5 | L24: =MROUND(H24,0.25)+2.25 -> 54.5 | M24: =MROUND(I24,0.25)+2.25 -> 56.5 | N24: =MROUND(J24,0.25)+2.25 -> 58.5
A25: GRAPE TOMATO / RED GRAPE (50 X 2.5oz) | B25: GRAPE TOMATO (50 X 2oz) | E25: GRAPES, RED (50 X 3oz) | F25: =(VLOOKUP($B25,'Master Item List'!$A$1:$V$320,13,FALSE)+VLOOKUP($E25,'Master Item List'!$A$1:$V$320,13,FALSE))/2 -> 26.247908 | G25: =$F25*1.25 -> 32.809886 | H25: =$F25*1.3 -> 34.122281 | I25: =$F25*1.35 -> 35.434676 | J25: =$F25*1.4 -> 36.747072 | K25: =MROUND(G25,0.25)+2.25 -> 35 | L25: =MROUND(H25,0.25)+2.25 -> 36.25 | M25: =MROUND(I25,0.25)+2.25 -> 37.75 | N25: =MROUND(J25,0.25)+2.25 -> 39
A26: GRAPE TOMATO / MANGO (50 X 2oz) | B26: GRAPE TOMATO (50 X 2oz) | E26: MANGO, CHUNKS (50x2oz) | F26: =(VLOOKUP($B26,'Master Item List'!$A$1:$V$320,13,FALSE)+VLOOKUP($E26,'Master Item List'!$A$1:$V$320,13,FALSE))/2 -> 25.357353 | G26: =$F26*1.25 -> 31.696691 | H26: =$F26*1.3 -> 32.964559 | I26: =$F26*1.35 -> 34.232426 | J26: =$F26*1.4 -> 35.500294 | K26: =MROUND(G26,0.25)+2.25 -> 34 | L26: =MROUND(H26,0.25)+2.25 -> 35.25 | M26: =MROUND(I26,0.25)+2.25 -> 36.5 | N26: =MROUND(J26,0.25)+2.25 -> 37.75
A27: HONEYDEW / GRAPES (50 X 2.7oz) | B27: HONEYDEW, CUBED, (50 X 2.7oz) | E27: ='Master Item List'!A61 -> GRAPES, RED (5# CASE) | F27: =(VLOOKUP($B27,'Master Item List'!$A$1:$V$320,13,FALSE)+VLOOKUP($E27,'Master Item List'!$A$1:$V$320,13,FALSE)) -> 45.577111 | G27: =$F27*1.25 -> 56.971389 | H27: =$F27*1.3 -> 59.250244 | I27: =$F27*1.35 -> 61.5291 | J27: =$F27*1.4 -> 63.807956 | K27: =MROUND(G27,0.25)+2.25 -> 59.25 | L27: =MROUND(H27,0.25)+2.25 -> 61.5 | M27: =MROUND(I27,0.25)+2.25 -> 63.75 | N27: =MROUND(J27,0.25)+2.25 -> 66
A28: HONEDEW / PINEAPPLES (50 X 2.3oz) | B28: HONEYDEW, CUBED, (50 X 2.7oz) | E28: PINEAPPLE (50 X 2.3oz) | F28: =(VLOOKUP($B28,'Master Item List'!$A$1:$V$320,13,FALSE)+VLOOKUP($E28,'Master Item List'!$A$1:$V$320,13,FALSE))/2 -> 25.076772 | G28: =$F28*1.25 -> 31.345965 | H28: =$F28*1.3 -> 32.599804 | I28: =$F28*1.35 -> 33.853642 | J28: =$F28*1.4 -> 35.107481 | K28: =MROUND(G28,0.25)+2.25 -> 33.5 | L28: =MROUND(H28,0.25)+2.25 -> 34.75 | M28: =MROUND(I28,0.25)+2.25 -> 36 | N28: =MROUND(J28,0.25)+2.25 -> 37.25
A29: JICAMA / GRAPES (50 X 2.3oz) | B29: JICAMA, STICKS (50 X 2oz) | E29: ='Master Item List'!A61 -> GRAPES, RED (5# CASE) | F29: =(VLOOKUP($B29,'Master Item List'!$A$1:$V$320,13,FALSE)+VLOOKUP($E29,'Master Item List'!$A$1:$V$320,13,FALSE)) -> 38.915278 | G29: =$F29*1.25 -> 48.644097 | H29: =$F29*1.3 -> 50.589861 | I29: =$F29*1.35 -> 52.535625 | J29: =$F29*1.4 -> 54.481389 | K29: =MROUND(G29,0.25)+2.25 -> 51 | L29: =MROUND(H29,0.25)+2.25 -> 52.75 | M29: =MROUND(I29,0.25)+2.25 -> 54.75 | N29: =MROUND(J29,0.25)+2.25 -> 56.75
A30: JICAMA / MANGO (50 X 2oz) | B30: JICAMA, STICKS (50 X 2oz) | E30: MANGO, CHUNKS (50x2oz) | F30: =(VLOOKUP($B30,'Master Item List'!$A$1:$V$320,13,FALSE)+VLOOKUP($E30,'Master Item List'!$A$1:$V$320,13,FALSE))/2 -> 23.69375 | G30: =$F30*1.25 -> 29.617188 | H30: =$F30*1.3 -> 30.801875 | I30: =$F30*1.35 -> 31.986563 | J30: =$F30*1.4 -> 33.17125 | K30: =MROUND(G30,0.25)+2.25 -> 31.75 | L30: =MROUND(H30,0.25)+2.25 -> 33 | M30: =MROUND(I30,0.25)+2.25 -> 34.25 | N30: =MROUND(J30,0.25)+2.25 -> 35.5
